Workbook

Sheet 1 · BBDD Casos incluidos
A1: País (ISO-2) | B1: Caso | C1: caso_id | D1: Año | E1: Confianza | F1: Descripción del proceso | G1: Organización a cargo | H1: Notas de validación | I1: Comentarios | J1: URLs | K1: Cuenta como iniciativa | L1: Tipo de proceso | M1: Etapas uso IA | N1: Nivel (0-3) | O1: Continuidad (etiqueta) | P1: Convocante (7-cat) | Q1: Tipo org | R1: Rol IA | S1: Tipo desarrollador IA | T1: Origen desarrollador | U1: Tipos/familia IA | V1: Usa LLM | W1: norm · Tipo de proceso | X1: norm · Etapas | Y1: norm · Convocante | Z1: norm · Tipo desarrollador | AA1: norm · Origen desarrollador | AB1: norm · Tipos/familia IA | AC1: TP: Participación Digital (0/1) | AD1: TP: Gobernanza Colaborativa (0/1) | AE1: TP: Mini públicos (0/1) | AF1: TP: Referendos e Iniciativas Populares (0/1) | AG1: TP: Presupuestos Participativos (0/1) | AH1: ET: Planificación (0/1) | AI1: ET: Implementación (0/1) | AJ1: ET: Análisis (0/1) | AK1: ET: Traducción Política (0/1) | AL1: CV: gobierno local [GL] (0/1) | AM1: CV: gobierno nacional [GN] (0/1) | AN1: CV: otra institución pública [OIP] (0/1) | AO1: CV: empresa [EMP] (0/1) | AP1: CV: universidad [UNI] (0/1) | AQ1: CV: sociedad civil [SC] (0/1) | AR1: CV: organización internacional [OI] (0/1) | AS1: DEV: Privado (0/1) | AT1: DEV: Academia (0/1) | AU1: DEV: Gobierno (0/1) | AV1: DEV: Sociedad Civil (0/1) | AW1: ORG: Nacional (0/1) | AX1: ORG: Internacional (0/1) | AY1: Nivel efectivo | AZ1: Clave combinación convocantes | BA1: Combinación 1ª aparición (país)
A2: BR | B2: 5ª Conferência Nacional de CT&I - sistematización con IA | C2: BR-5a-conferencia-nacional-de-ct-i-sistemat | D2: 2023 | E2: ALTA | F2: Proceso participativo de consulta pública nacional para la construcción de la nueva Estrategia Nacional de Ciencia, Tecnología e Innovación (ENCTI 2030). Comprendió más de 200 etapas preparatorias (18 reuniones temáticas, 157 conferencias libres, 27 conferencias estaduales, 14 municipales y 5 regionales), con más de 100 mil participantes en 221 eventos, culminando en la etapa nacional en Brasília (30-31 jul y 1 ago 2024). La Subcomissão de Sistematização e Documentação usó IA para transcribir, analizar, sistematizar y sintetizar las contribuciones, produciendo e-books de síntesis y los Libros Lilás (rec. de la sociedad) y Violeta (documento de referencia) que orientan la ENCTI. | G2: Ministério da Ciência, Tecnologia e Inovação (MCTI), con organización del Centro de Gestão e Estudos Estratégicos (CGEE). La sistematización con IA fue ejecutada por la empresa TDS Company (Porto Digital, Recife, PE) con curaduría de la Subcomissão de Sistematização e Documentação, coordinada por Francilene Garcia. | J2: https://www.gov.br/mcti/pt-br/acompanhe-o-mcti/noticias/2024/08/5a-conferencia-nacional-de-ciencia-tecnologia-e-inovacao-na-era-digital-tem-publico-recorde-lancamento-de-plano-de-ia-e-debates-sobre-temas-urgentes | K2: sí | L2: Participación Digital; Gobernanza Colaborativa | M2: Análisis | N2: 2 | O2: Uso único | P2: gobierno nacional | Q2: Público | R2: contenido | S2: Privado | T2: Nacional | U2: Voz a Texto; NLP | V2: no-claro | W2: =";"&LOWER(SUBSTITUTE(SUBSTITUTE(SUBSTITUTE(L2,"; ",";"),", ",";"),",",";"))&";" -> ;participación digital;gobernanza colaborativa; | X2: =";"&LOWER(SUBSTITUTE(SUBSTITUTE(SUBSTITUTE(M2,"; ",";"),", ",";"),",",";"))&";" -> ;análisis; | Y2: =";"&LOWER(SUBSTITUTE(SUBSTITUTE(SUBSTITUTE(P2,"; ",";"),", ",";"),",",";"))&";" -> ;gobierno nacional; | Z2: =";"&LOWER(SUBSTITUTE(SUBSTITUTE(SUBSTITUTE(S2,"; ",";"),", ",";"),",",";"))&";" -> ;privado; | AA2: =";"&LOWER(SUBSTITUTE(SUBSTITUTE(SUBSTITUTE(T2,"; ",";"),", ",";"),",",";"))&";" -> ;nacional; | AB2: =";"&LOWER(SUBSTITUTE(SUBSTITUTE(SUBSTITUTE(U2,"; ",";"),", ",";"),",",";"))&";" -> ;voz a texto;nlp; | AC2: =IF(ISNUMBER(SEARCH(";participación digital;",W2)),1,0) -> 1 | AD2: =IF(ISNUMBER(SEARCH(";gobernanza colaborativa;",W2)),1,0) -> 1 | AE2: =IF(ISNUMBER(SEARCH(";mini públicos;",W2)),1,0) -> 0 | AF2: =IF(ISNUMBER(SEARCH(";referendos e iniciativas populares;",W2)),1,0) -> 0 | AG2: =IF(ISNUMBER(SEARCH(";presupuestos participativos;",W2)),1,0) -> 0 | AH2: =IF(ISNUMBER(SEARCH(";planificación;",X2)),1,0) -> 0 | AI2: =IF(ISNUMBER(SEARCH(";implementación;",X2)),1,0) -> 0 | AJ2: =IF(ISNUMBER(SEARCH(";análisis;",X2)),1,0) -> 1 | AK2: =IF(ISNUMBER(SEARCH("traducción",X2)),1,0) -> 0 | AL2: =IF(ISNUMBER(SEARCH(";gobierno local;",Y2)),1,0) -> 0 | AM2: =IF(ISNUMBER(SEARCH(";gobierno nacional;",Y2)),1,0) -> 1 | AN2: =IF(ISNUMBER(SEARCH(";otra institución pública;",Y2)),1,0) -> 0 | AO2: =IF(ISNUMBER(SEARCH(";empresa;",Y2)),1,0) -> 0 | AP2: =IF(ISNUMBER(SEARCH(";universidad;",Y2)),1,0) -> 0 | AQ2: =IF(ISNUMBER(SEARCH(";sociedad civil;",Y2)),1,0) -> 0 | AR2: =IF(ISNUMBER(SEARCH(";organización internacional;",Y2)),1,0) -> 0 | AS2: =IF(ISNUMBER(SEARCH(";privado;",Z2)),1,0) -> 1 | AT2: =IF(ISNUMBER(SEARCH(";academia;",Z2)),1,0) -> 0 | AU2: =IF(ISNUMBER(SEARCH(";gobierno;",Z2)),1,0) -> 0 | AV2: =IF(ISNUMBER(SEARCH(";sociedad civil;",Z2)),1,0) -> 0 | AW2: =IF(ISNUMBER(SEARCH(";nacional;",AA2)),1,0) -> 1 | AX2: =IF(ISNUMBER(SEARCH(";internacional;",AA2)),1,0) -> 0 | AY2: =IF(AND(N2=1,('2 · Índice por país'!$B$25-D2)>'2 · Índice por país'!$B$26),0,N2) -> 2 | AZ2: =IF(SUM(AL2:AR2)<2,"",IF(AL2=1,"GL+","")&IF(AM2=1,"GN+","")&IF(AN2=1,"OIP+","")&IF(AO2=1,"EMP+","")&IF(AP2=1,"UNI+","")&IF(AQ2=1,"SC+","")&IF(AR2=1,"OI+","")) | BA2: =IF(AZ2="",0,IF(COUNTIFS($A$1:$A1,A2,$AZ$1:$AZ1,AZ2)=0,1,0)) -> 0
A3: BO | B3: Bolivia Conversa | C3: BO-bolivia-conversa | D3: 2021 | E3: ALTA (baseline 2025 + reverif. web 2026) | F3: Plataforma de diálogo digital que emplea IA para procesar y agrupar aportaciones ciudadanas en tiempo real, retornando feedback inmediato y garantizando anonimato, con vistas a fomentar el reencuentro y la cohesión social en el país. | G3: Vicepresidencia del Estado Plurinacional de Bolivia y Sistema de Naciones Unidas en Bolivia | J3: https://bolivia.un.org/es/216764-%E2%80%9Cbolivia-conversa%E2%80%9D-%C2%BFc%C3%B3mo-la-tecnolog%C3%ADa-puede-ayudar-promover-el-di%C3%A1logo | K3: sí | L3: Gobernanza Colaborativa | M3: Implementación; Análisis | N3: 2 | O3: Uso único | P3: gobierno nacional; organización internacional | Q3: Público | R3: contenido | S3: Privado | T3: Internacional | U3: NLP - Tópicos | V3: no | W3: =";"&LOWER(SUBSTITUTE(SUBSTITUTE(SUBSTITUTE(L3,"; ",";"),", ",";"),",",";"))&";" -> ;gobernanza colaborativa; | X3: =";"&LOWER(SUBSTITUTE(SUBSTITUTE(SUBSTITUTE(M3,"; ",";"),", ",";"),",",";"))&";" -> ;implementación;análisis; | Y3: =";"&LOWER(SUBSTITUTE(SUBSTITUTE(SUBSTITUTE(P3,"; ",";"),", ",";"),",",";"))&";" -> ;gobierno nacional;organización internacional; | Z3: =";"&LOWER(SUBSTITUTE(SUBSTITUTE(SUBSTITUTE(S3,"; ",";"),", ",";"),",",";"))&";" -> ;privado; | AA3: =";"&LOWER(SUBSTITUTE(SUBSTITUTE(SUBSTITUTE(T3,"; ",";"),", ",";"),",",";"))&";" -> ;internacional; | AB3: =";"&LOWER(SUBSTITUTE(SUBSTITUTE(SUBSTITUTE(U3,"; ",";"),", ",";"),",",";"))&";" -> ;nlp - tópicos; | AC3: =IF(ISNUMBER(SEARCH(";participación digital;",W3)),1,0) -> 0 | AD3: =IF(ISNUMBER(SEARCH(";gobernanza colaborativa;",W3)),1,0) -> 1 | AE3: =IF(ISNUMBER(SEARCH(";mini públicos;",W3)),1,0) -> 0 | AF3: =IF(ISNUMBER(SEARCH(";referendos e iniciativas populares;",W3)),1,0) -> 0 | AG3: =IF(ISNUMBER(SEARCH(";presupuestos participativos;",W3)),1,0) -> 0 | AH3: =IF(ISNUMBER(SEARCH(";planificación;",X3)),1,0) -> 0 | AI3: =IF(ISNUMBER(SEARCH(";implementación;",X3)),1,0) -> 1 | AJ3: =IF(ISNUMBER(SEARCH(";análisis;",X3)),1,0) -> 1 | AK3: =IF(ISNUMBER(SEARCH("traducción",X3)),1,0) -> 0 | AL3: =IF(ISNUMBER(SEARCH(";gobierno local;",Y3)),1,0) -> 0 | AM3: =IF(ISNUMBER(SEARCH(";gobierno nacional;",Y3)),1,0) -> 1 | AN3: =IF(ISNUMBER(SEARCH(";otra institución pública;",Y3)),1,0) -> 0 | AO3: =IF(ISNUMBER(SEARCH(";empresa;",Y3)),1,0) -> 0 | AP3: =IF(ISNUMBER(SEARCH(";universidad;",Y3)),1,0) -> 0 | AQ3: =IF(ISNUMBER(SEARCH(";sociedad civil;",Y3)),1,0) -> 0 | AR3: =IF(ISNUMBER(SEARCH(";organización internacional;",Y3)),1,0) -> 1 | AS3: =IF(ISNUMBER(SEARCH(";privado;",Z3)),1,0) -> 1 | AT3: =IF(ISNUMBER(SEARCH(";academia;",Z3)),1,0) -> 0 | AU3: =IF(ISNUMBER(SEARCH(";gobierno;",Z3)),1,0) -> 0 | AV3: =IF(ISNUMBER(SEARCH(";sociedad civil;",Z3)),1,0) -> 0 | AW3: =IF(ISNUMBER(SEARCH(";nacional;",AA3)),1,0) -> 0 | AX3: =IF(ISNUMBER(SEARCH(";internacional;",AA3)),1,0) -> 1 | AY3: =IF(AND(N3=1,('2 · Índice por país'!$B$25-D3)>'2 · Índice por país'!$B$26),0,N3) -> 2 | AZ3: =IF(SUM(AL3:AR3)<2,"",IF(AL3=1,"GL+","")&IF(AM3=1,"GN+","")&IF(AN3=1,"OIP+","")&IF(AO3=1,"EMP+","")&IF(AP3=1,"UNI+","")&IF(AQ3=1,"SC+","")&IF(AR3=1,"OI+","")) -> GN+OI+ | BA3: =IF(AZ3="",0,IF(COUNTIFS($A$1:$A2,A3,$AZ$1:$AZ2,AZ3)=0,1,0)) -> 1
A4: BR | B4: Brasil Participativo - clustering semántico de propuestas ciudadanas (BERTopic + LLM, alineado a VCGE) | C4: BR-brasil-participativo-clustering-semantic | D4: 2023 | E4: MEDIA | F4: Brasil Participativo es la plataforma digital de participación social del Gobierno Federal de Brasil (construida sobre el software libre Decidim), lanzada en 2023 por la Secretaria-Geral da Presidência da República. En ella la ciudadanía envía propuestas de texto libre, revisiones, comentarios y votos sobre políticas públicas en procesos participativos federales reales: el Plano Plurianual Participativo (PPA 2024-2027), el Plano Clima Participativo y el Congresso da Juventude, además de conferencias y consultas públicas. Sobre el contenido de esas propuestas, equipos de la Universidade de Brasília (LAPPIS/FGA-UnB) y la Residência TIC BRISA desarrollaron un pipeline de IA que recolecta, clasifica y agrupa por temas las propuestas: combina modelado de tópicos con BERTopic (probando varios embeddings: BERTimbau, LaBSE, GovBERT-BR, etc.), incorpora conocimiento institucional mediante seed words extraídas del VCGE (Vocabulário Controlado do Governo Eletrônico) y usa LLMs para el etiquetado/validación automática de los tópicos, generando categorías y reportes temáticos consistentes con la taxonomía oficial para apoyar a los equipos de formulación de políticas. Se documenta un pipeline ML en evolución hacia producción (paper 'From Pre-labeling to Production') y un clasificador ML adicional (BP-Classificador-de-Propostas) entrenado a diario con Apache Airflow con datos de la plataforma, descrito como destinado a integrarse en la plataforma. | G4: Plataforma: Secretaria-Geral da Presidência da República (Secretaria Nacional de Participação Social), Gobierno Federal de Brasil, con desarrollo de la plataforma a cargo de LAPPIS/FGA-UnB y la comunidad Decidim-Brasil (Dataprev). Componente de IA (clustering semántico / clasificador): investigadores de la Universidade de Brasília (LAPPIS) y la Residência TIC BRISA (UnB-Gama / BRISA), con la Secretaria de Participação Social como mentora del proyecto. | H4: Yo lo dejaría, pero como anuncio dado que no se ve que haya sido implementado todavía en las fuentes que tenemos | I4: No hay fuente que respalde el uso de IA activo en la iniciativa. Solo un paper donde se promueve su implementación | K4: sí | L4: Gobernanza Colaborativa; Participación Digital | M4: Análisis | N4: 1 | O4: Anuncio | P4: gobierno nacional | Q4: Público | R4: contenido | S4: Academia; Gobierno | T4: Nacional | U4: NLP; Topic modeling; Clustering semántico; Clasificación de texto; Embeddings; LLM | V4: sí | W4: =";"&LOWER(SUBSTITUTE(SUBSTITUTE(SUBSTITUTE(L4,"; ",";"),", ",";"),",",";"))&";" -> ;gobernanza colaborativa;participación digital; | X4: =";"&LOWER(SUBSTITUTE(SUBSTITUTE(SUBSTITUTE(M4,"; ",";"),", ",";"),",",";"))&";" -> ;análisis; | Y4: =";"&LOWER(SUBSTITUTE(SUBSTITUTE(SUBSTITUTE(P4,"; ",";"),", ",";"),",",";"))&";" -> ;gobierno nacional; | Z4: =";"&LOWER(SUBSTITUTE(SUBSTITUTE(SUBSTITUTE(S4,"; ",";"),", ",";"),",",";"))&";" -> ;academia;gobierno; | AA4: =";"&LOWER(SUBSTITUTE(SUBSTITUTE(SUBSTITUTE(T4,"; ",";"),", ",";"),",",";"))&";" -> ;nacional; | AB4: =";"&LOWER(SUBSTITUTE(SUBSTITUTE(SUBSTITUTE(U4,"; ",";"),", ",";"),",",";"))&";" -> ;nlp;topic modeling;clustering semántico;clasificación de texto;embeddings;llm; | AC4: =IF(ISNUMBER(SEARCH(";participación digital;",W4)),1,0) -> 1 | AD4: =IF(ISNUMBER(SEARCH(";gobernanza colaborativa;",W4)),1,0) -> 1 | AE4: =IF(ISNUMBER(SEARCH(";mini públicos;",W4)),1,0) -> 0 | AF4: =IF(ISNUMBER(SEARCH(";referendos e iniciativas populares;",W4)),1,0) -> 0 | AG4: =IF(ISNUMBER(SEARCH(";presupuestos participativos;",W4)),1,0) -> 0 | AH4: =IF(ISNUMBER(SEARCH(";planificación;",X4)),1,0) -> 0 | AI4: =IF(ISNUMBER(SEARCH(";implementación;",X4)),1,0) -> 0 | AJ4: =IF(ISNUMBER(SEARCH(";análisis;",X4)),1,0) -> 1 | AK4: =IF(ISNUMBER(SEARCH("traducción",X4)),1,0) -> 0 | AL4: =IF(ISNUMBER(SEARCH(";gobierno local;",Y4)),1,0) -> 0 | AM4: =IF(ISNUMBER(SEARCH(";gobierno nacional;",Y4)),1,0) -> 1 | AN4: =IF(ISNUMBER(SEARCH(";otra institución pública;",Y4)),1,0) -> 0 | AO4: =IF(ISNUMBER(SEARCH(";empresa;",Y4)),1,0) -> 0 | AP4: =IF(ISNUMBER(SEARCH(";universidad;",Y4)),1,0) -> 0 | AQ4: =IF(ISNUMBER(SEARCH(";sociedad civil;",Y4)),1,0) -> 0 | AR4: =IF(ISNUMBER(SEARCH(";organización internacional;",Y4)),1,0) -> 0 | AS4: =IF(ISNUMBER(SEARCH(";privado;",Z4)),1,0) -> 0 | AT4: =IF(ISNUMBER(SEARCH(";academia;",Z4)),1,0) -> 1 | AU4: =IF(ISNUMBER(SEARCH(";gobierno;",Z4)),1,0) -> 1 | AV4: =IF(ISNUMBER(SEARCH(";sociedad civil;",Z4)),1,0) -> 0 | AW4: =IF(ISNUMBER(SEARCH(";nacional;",AA4)),1,0) -> 1 | AX4: =IF(ISNUMBER(SEARCH(";internacional;",AA4)),1,0) -> 0 | AY4: =IF(AND(N4=1,('2 · Índice por país'!$B$25-D4)>'2 · Índice por país'!$B$26),0,N4) -> 0 | AZ4: =IF(SUM(AL4:AR4)<2,"",IF(AL4=1,"GL+","")&IF(AM4=1,"GN+","")&IF(AN4=1,"OIP+","")&IF(AO4=1,"EMP+","")&IF(AP4=1,"UNI+","")&IF(AQ4=1,"SC+","")&IF(AR4=1,"OI+","")) | BA4: =IF(AZ4="",0,IF(COUNTIFS($A$1:$A3,A4,$AZ$1:$AZ3,AZ4)=0,1,0)) -> 0
A5: BR | B5: Meta Community Forum on Generative AI — cohorte Brasil (Deliberative Polling, Stanford) | C5: BR-meta-community-forum-genai | D5: 2023 | E5: ALTA (plataforma, moderador automatizado, fechas, cohorte BR y hallazgos BR confirmados con citas verbatim de Stanford/BIT); pendiente solo N de Brasil e idioma, y el pipeline de análisis (posible upgrade a 'contenido') | F5: Foro comunitario deliberativo (Deliberative Polling®) sobre principios para los chatbots de IA generativa, realizado el 28-29 de octubre de 2023 en la Stanford Online Deliberation Platform con 1.545 participantes de muestras científicas de Brasil, Alemania, España y EE.UU. Formato: grupos pequeños de 8-12 personas (166 grupos, con grupo de control por país), panel de expertos en plenario, cuadernillo informativo (~50 págs.) y 44 preguntas de opinión pre/post. Los resultados (publicados abr-2024) incluyen hallazgos específicos de Brasil (p. ej., fuerte oposición a relaciones románticas humano-chatbot; énfasis en perspectivas locales en las fuentes de la IA). Meta declaró que los resultados 'ayudaron a dar forma a algunas de las decisiones más fundamentales' del diseño de sus productos de IA generativa. | G5: Meta (convocante/financista) + Stanford Deliberative Democracy Lab (diseño y ejecución del Deliberative Polling®) + Behavioural Insights Team (entrega y recomendaciones) | H5: Entra como «apoyo» (moderador automatizado de la deliberación). Pendiente: confirmar N de la cohorte Brasil e idioma, y si el pipeline de análisis toca el CONTENIDO de los aportes (posible upgrade rol_IA apoyo→contenido). Fuentes Stanford DDL / BIT ya citadas. | J5: https://deliberation.stanford.edu/meta-community-forum-generative-ai-results | K5: sí | L5: Mini públicos | M5: Implementación | N5: 2 | O5: Uso único | P5: empresa; universidad | Q5: Privado | R5: apoyo | S5: Academia | T5: Internacional | U5: Moderación/facilitación automatizada; Sistema de reglas/temporización | V5: no-claro | W5: =";"&LOWER(SUBSTITUTE(SUBSTITUTE(SUBSTITUTE(L5,"; ",";"),", ",";"),",",";"))&";" -> ;mini públicos; | X5: =";"&LOWER(SUBSTITUTE(SUBSTITUTE(SUBSTITUTE(M5,"; ",";"),", ",";"),",",";"))&";" -> ;implementación; | Y5: =";"&LOWER(SUBSTITUTE(SUBSTITUTE(SUBSTITUTE(P5,"; ",";"),", ",";"),",",";"))&";" -> ;empresa;universidad; | Z5: =";"&LOWER(SUBSTITUTE(SUBSTITUTE(SUBSTITUTE(S5,"; ",";"),", ",";"),",",";"))&";" -> ;academia; | AA5: =";"&LOWER(SUBSTITUTE(SUBSTITUTE(SUBSTITUTE(T5,"; ",";"),", ",";"),",",";"))&";" -> ;internacional; | AB5: =";"&LOWER(SUBSTITUTE(SUBSTITUTE(SUBSTITUTE(U5,"; ",";"),", ",";"),",",";"))&";" -> ;moderación/facilitación automatizada;sistema de reglas/temporización; | AC5: =IF(ISNUMBER(SEARCH(";participación digital;",W5)),1,0) -> 0 | AD5: =IF(ISNUMBER(SEARCH(";gobernanza colaborativa;",W5)),1,0) -> 0 | AE5: =IF(ISNUMBER(SEARCH(";mini públicos;",W5)),1,0) -> 1 | AF5: =IF(ISNUMBER(SEARCH(";referendos e iniciativas populares;",W5)),1,0) -> 0 | AG5: =IF(ISNUMBER(SEARCH(";presupuestos participativos;",W5)),1,0) -> 0 | AH5: =IF(ISNUMBER(SEARCH(";planificación;",X5)),1,0) -> 0 | AI5: =IF(ISNUMBER(SEARCH(";implementación;",X5)),1,0) -> 1 | AJ5: =IF(ISNUMBER(SEARCH(";análisis;",X5)),1,0) -> 0 | AK5: =IF(ISNUMBER(SEARCH("traducción",X5)),1,0) -> 0 | AL5: =IF(ISNUMBER(SEARCH(";gobierno local;",Y5)),1,0) -> 0 | AM5: =IF(ISNUMBER(SEARCH(";gobierno nacional;",Y5)),1,0) -> 0 | AN5: =IF(ISNUMBER(SEARCH(";otra institución pública;",Y5)),1,0) -> 0 | AO5: =IF(ISNUMBER(SEARCH(";empresa;",Y5)),1,0) -> 1 | AP5: =IF(ISNUMBER(SEARCH(";universidad;",Y5)),1,0) -> 1 | AQ5: =IF(ISNUMBER(SEARCH(";sociedad civil;",Y5)),1,0) -> 0 | AR5: =IF(ISNUMBER(SEARCH(";organización internacional;",Y5)),1,0) -> 0 | AS5: =IF(ISNUMBER(SEARCH(";privado;",Z5)),1,0) -> 0 | AT5: =IF(ISNUMBER(SEARCH(";academia;",Z5)),1,0) -> 1 | AU5: =IF(ISNUMBER(SEARCH(";gobierno;",Z5)),1,0) -> 0 | AV5: =IF(ISNUMBER(SEARCH(";sociedad civil;",Z5)),1,0) -> 0 | AW5: =IF(ISNUMBER(SEARCH(";nacional;",AA5)),1,0) -> 0 | AX5: =IF(ISNUMBER(SEARCH(";internacional;",AA5)),1,0) -> 1 | AY5: =IF(AND(N5=1,('2 · Índice por país'!$B$25-D5)>'2 · Índice por país'!$B$26),0,N5) -> 2 | AZ5: =IF(SUM(AL5:AR5)<2,"",IF(AL5=1,"GL+","")&IF(AM5=1,"GN+","")&IF(AN5=1,"OIP+","")&IF(AO5=1,"EMP+","")&IF(AP5=1,"UNI+","")&IF(AQ5=1,"SC+","")&IF(AR5=1,"OI+","")) -> EMP+UNI+ | BA5: =IF(AZ5="",0,IF(COUNTIFS($A$1:$A4,A5,$AZ$1:$AZ4,AZ5)=0,1,0)) -> 1
A6: BR | B6: OPA Piauí - Orçamento Participativo Digital (Colab) | C6: BR-opa-piaui-presupuesto-participativo-digi | D6: 2023 | E6: MEDIA | F6: OPA (Orçamento Participativo Digital) es el presupuesto participativo 100% digital del Gobierno del Estado de Piauí (Brasil), creado en 2023 y coordinado por la Secretaria do Planejamento (SEPLAN) con apoyo de la Secretaria de Relações Sociais (Seres). Se ejecuta sobre la plataforma Colab Gov (de la govtech Colab) con infraestructura AWS. El ciclo incluye cadastramento de propuestas por entidades comunitarias/asociaciones, una fase de 'análise técnica' (verificación de documentación, viabilidad de ejecución, claridad de la descripción, adecuación al área temática y no duplicación) y una votación popular abierta a la ciudadanía. En la edición 2026-2027, según el material de Colab, 'a análise ganhou agilidade com o uso de inteligência artificial, que reduziu em 40% o tempo de processamento das propostas', con economía de R$ 1,75 millón y 99,98% de disponibilidad del sistema. La señal disponible vincula la IA al procesamiento/agilización del flujo, a la seguridad de la infraestructura (filtrado de conexiones inseguras vía AWS CloudFront), a un chatbot/capacitación (CapacitIA) y a un 'Observatório do OPA' de transparencia; la 'análise técnica' de viabilidad se describe de forma reiterada como tarea conducida por equipos técnicos a través de la plataforma. NO hay evidencia de que la IA clasifique, agrupe (clustering) o sintetice el CONTENIDO temático/semántico de las propuestas en el OPA. | G6: Governo do Estado do Piauí - Secretaria do Planejamento (SEPLAN), con apoyo de la Secretaria de Relações Sociais (Seres). Socio tecnológico: GovTech Colab (plataforma Colab Gov); infraestructura: AWS (Amazon Web Services). | H6: Caso con más huecos y rol_IA dudoso. (1) Definir rol_IA: la evidencia dice que la IA agiliza el flujo y la seguridad y reduce ~40% el tiempo de análisis, SIN traza de que clasifique/agrupe/sintetice el CONTENIDO de las propuestas → hoy «apoyo»; confirmar en la fuente si hay análisis de contenido (subiría a «contenido»). (2) Completar «Tipos/familia IA» (vacío). (3) Faltan citas en Evidencia: etapas_uso_IA, estado_actividad, nivel_consolidación, tipo_convocante y usa_IA_en_proceso — abrir las URLs (Colab / SEPLAN) y extraer verbatim. | I6: No se especifica tan bien como es el uso de la IA, pero lo menciona | J6: https://www.colab.com.br/noticias/opa-e-a-participacao-popular-como-as-plataformas-colab-fortalecem-o-processo-participativo-no-piaui/ | K6: sí | L6: Presupuestos Participativos; Participación Digital | M6: Implementación | N6: 3 | O6: Plataforma | P6: gobierno local | Q6: Público | R6: apoyo | S6: Privado | T6: Nacional | V6: no-claro | W6: =";"&LOWER(SUBSTITUTE(SUBSTITUTE(SUBSTITUTE(L6,"; ",";"),", ",";"),",",";"))&";" -> ;presupuestos participativos;participación digital; | X6: =";"&LOWER(SUBSTITUTE(SUBSTITUTE(SUBSTITUTE(M6,"; ",";"),", ",";"),",",";"))&";" -> ;implementación; | Y6: =";"&LOWER(SUBSTITUTE(SUBSTITUTE(SUBSTITUTE(P6,"; ",";"),", ",";"),",",";"))&";" -> ;gobierno local; | Z6: =";"&LOWER(SUBSTITUTE(SUBSTITUTE(SUBSTITUTE(S6,"; ",";"),", ",";"),",",";"))&";" -> ;privado; | AA6: =";"&LOWER(SUBSTITUTE(SUBSTITUTE(SUBSTITUTE(T6,"; ",";"),", ",";"),",",";"))&";" -> ;nacional; | AB6: =";"&LOWER(SUBSTITUTE(SUBSTITUTE(SUBSTITUTE(U6,"; ",";"),", ",";"),",",";"))&";" -> ;; | AC6: =IF(ISNUMBER(SEARCH(";participación digital;",W6)),1,0) -> 1 | AD6: =IF(ISNUMBER(SEARCH(";gobernanza colaborativa;",W6)),1,0) -> 0 | AE6: =IF(ISNUMBER(SEARCH(";mini públicos;",W6)),1,0) -> 0 | AF6: =IF(ISNUMBER(SEARCH(";referendos e iniciativas populares;",W6)),1,0) -> 0 | AG6: =IF(ISNUMBER(SEARCH(";presupuestos participativos;",W6)),1,0) -> 1 | AH6: =IF(ISNUMBER(SEARCH(";planificación;",X6)),1,0) -> 0 | AI6: =IF(ISNUMBER(SEARCH(";implementación;",X6)),1,0) -> 1 | AJ6: =IF(ISNUMBER(SEARCH(";análisis;",X6)),1,0) -> 0 | AK6: =IF(ISNUMBER(SEARCH("traducción",X6)),1,0) -> 0 | AL6: =IF(ISNUMBER(SEARCH(";gobierno local;",Y6)),1,0) -> 1 | AM6: =IF(ISNUMBER(SEARCH(";gobierno nacional;",Y6)),1,0) -> 0 | AN6: =IF(ISNUMBER(SEARCH(";otra institución pública;",Y6)),1,0) -> 0 | AO6: =IF(ISNUMBER(SEARCH(";empresa;",Y6)),1,0) -> 0 | AP6: =IF(ISNUMBER(SEARCH(";universidad;",Y6)),1,0) -> 0 | AQ6: =IF(ISNUMBER(SEARCH(";sociedad civil;",Y6)),1,0) -> 0 | AR6: =IF(ISNUMBER(SEARCH(";organización internacional;",Y6)),1,0) -> 0 | AS6: =IF(ISNUMBER(SEARCH(";privado;",Z6)),1,0) -> 1 | AT6: =IF(ISNUMBER(SEARCH(";academia;",Z6)),1,0) -> 0 | AU6: =IF(ISNUMBER(SEARCH(";gobierno;",Z6)),1,0) -> 0 | AV6: =IF(ISNUMBER(SEARCH(";sociedad civil;",Z6)),1,0) -> 0 | AW6: =IF(ISNUMBER(SEARCH(";nacional;",AA6)),1,0) -> 1 | AX6: =IF(ISNUMBER(SEARCH(";internacional;",AA6)),1,0) -> 0 | AY6: =IF(AND(N6=1,('2 · Índice por país'!$B$25-D6)>'2 · Índice por país'!$B$26),0,N6) -> 3 | AZ6: =IF(SUM(AL6:AR6)<2,"",IF(AL6=1,"GL+","")&IF(AM6=1,"GN+","")&IF(AN6=1,"OIP+","")&IF(AO6=1,"EMP+","")&IF(AP6=1,"UNI+","")&IF(AQ6=1,"SC+","")&IF(AR6=1,"OI+","")) | BA6: =IF(AZ6="",0,IF(COUNTIFS($A$1:$A5,A6,$AZ$1:$AZ5,AZ6)=0,1,0)) -> 0
A7: BR | B7: Plan Plurianual de la ciudad de Natal | C7: BR-plan-plurianual-de-la-ciudad-de-natal | D7: 2025 | E7: ALTA (baseline 2025 + reverif. web 2026) | F7: Recolección de información a través de tres preguntas habilitadas por WhatsApp para diseñar el Plan Plurianual de la ciudad 2026-2029 | G7: Prefeitura Municipal de Natal, a través de la Secretaría Municipal de Planeamiento (SEMPLA) | J7: https://diariodorn.com.br/prefeitura-de-natal-lanca-ppa-participativo-via-whatsapp-com-inteligencia-artificial/ | K7: sí | L7: Gobernanza Colaborativa | M7: Implementación; Análisis | N7: 2 | O7: Plataforma | P7: gobierno local | Q7: Público | R7: contenido | S7: Gobierno; Privado | T7: Nacional, Internacional | U7: LLM; NLP | V7: sí | W7: =";"&LOWER(SUBSTITUTE(SUBSTITUTE(SUBSTITUTE(L7,"; ",";"),", ",";"),",",";"))&";" -> ;gobernanza colaborativa; | X7: =";"&LOWER(SUBSTITUTE(SUBSTITUTE(SUBSTITUTE(M7,"; ",";"),", ",";"),",",";"))&";" -> ;implementación;análisis; | Y7: =";"&LOWER(SUBSTITUTE(SUBSTITUTE(SUBSTITUTE(P7,"; ",";"),", ",";"),",",";"))&";" -> ;gobierno local; | Z7: =";"&LOWER(SUBSTITUTE(SUBSTITUTE(SUBSTITUTE(S7,"; ",";"),", ",";"),",",";"))&";" -> ;gobierno;privado; | AA7: =";"&LOWER(SUBSTITUTE(SUBSTITUTE(SUBSTITUTE(T7,"; ",";"),", ",";"),",",";"))&";" -> ;nacional;internacional; | AB7: =";"&LOWER(SUBSTITUTE(SUBSTITUTE(SUBSTITUTE(U7,"; ",";"),", ",";"),",",";"))&";" -> ;llm;nlp; | AC7: =IF(ISNUMBER(SEARCH(";participación digital;",W7)),1,0) -> 0 | AD7: =IF(ISNUMBER(SEARCH(";gobernanza colaborativa;",W7)),1,0) -> 1 | AE7: =IF(ISNUMBER(SEARCH(";mini públicos;",W7)),1,0) -> 0 | AF7: =IF(ISNUMBER(SEARCH(";referendos e iniciativas populares;",W7)),1,0) -> 0 | AG7: =IF(ISNUMBER(SEARCH(";presupuestos participativos;",W7)),1,0) -> 0 | AH7: =IF(ISNUMBER(SEARCH(";planificación;",X7)),1,0) -> 0 | AI7: =IF(ISNUMBER(SEARCH(";implementación;",X7)),1,0) -> 1 | AJ7: =IF(ISNUMBER(SEARCH(";análisis;",X7)),1,0) -> 1 | AK7: =IF(ISNUMBER(SEARCH("traducción",X7)),1,0) -> 0 | AL7: =IF(ISNUMBER(SEARCH(";gobierno local;",Y7)),1,0) -> 1 | AM7: =IF(ISNUMBER(SEARCH(";gobierno nacional;",Y7)),1,0) -> 0 | AN7: =IF(ISNUMBER(SEARCH(";otra institución pública;",Y7)),1,0) -> 0 | AO7: =IF(ISNUMBER(SEARCH(";empresa;",Y7)),1,0) -> 0 | AP7: =IF(ISNUMBER(SEARCH(";universidad;",Y7)),1,0) -> 0 | AQ7: =IF(ISNUMBER(SEARCH(";sociedad civil;",Y7)),1,0) -> 0 | AR7: =IF(ISNUMBER(SEARCH(";organización internacional;",Y7)),1,0) -> 0 | AS7: =IF(ISNUMBER(SEARCH(";privado;",Z7)),1,0) -> 1 | AT7: =IF(ISNUMBER(SEARCH(";academia;",Z7)),1,0) -> 0 | AU7: =IF(ISNUMBER(SEARCH(";gobierno;",Z7)),1,0) -> 1 | AV7: =IF(ISNUMBER(SEARCH(";sociedad civil;",Z7)),1,0) -> 0 | AW7: =IF(ISNUMBER(SEARCH(";nacional;",AA7)),1,0) -> 1 | AX7: =IF(ISNUMBER(SEARCH(";internacional;",AA7)),1,0) -> 1 | AY7: =IF(AND(N7=1,('2 · Índice por país'!$B$25-D7)>'2 · Índice por país'!$B$26),0,N7) -> 2 | AZ7: =IF(SUM(AL7:AR7)<2,"",IF(AL7=1,"GL+","")&IF(AM7=1,"GN+","")&IF(AN7=1,"OIP+","")&IF(AO7=1,"EMP+","")&IF(AP7=1,"UNI+","")&IF(AQ7=1,"SC+","")&IF(AR7=1,"OI+","")) | BA7: =IF(AZ7="",0,IF(COUNTIFS($A$1:$A6,A7,$AZ$1:$AZ6,AZ7)=0,1,0)) -> 0
A8: BR | B8: Portal e-Cidadania (Senado Federal de Brasil) — IA sobre aportes ciudadanos: marcado automático de respuestas en audiencias públicas + matching semántico de ideias legislativas | C8: BR-e-cidadania-senado | D8: 2025 | E8: ALTA (baseline 2025 + reverif. web 2026; ambas herramientas) | F8: Portal e-Cidadania del Senado Federal de Brasil (plataforma de participación ciudadana). Aplica IA sobre los aportes ciudadanos en DOS herramientas del MISMO portal (cuentan como 1 iniciativa): (1) MARCADO DE AUDIENCIAS PÚBLICAS (2025): Implementación de IA para identificar y marcar en los videos de eventos las respuestas dadas a preguntas ciudadanas, incluso cuando estas no fueron respondidas directamente durante las audiencias. (2) MATCHING DE IDEIAS LEGISLATIVAS (dic-2025 / ene-2026): Portal e-Cidadania del Senado Federal de Brasil, módulo 'Ideia Legislativa', donde la población envía sugerencias para crear o mejorar leyes. Tradicionalmente una idea debía reunir 20.000 apoyos en 4 meses para ser formalizada como Sugestão Legislativa y analizada por la Comissão de Direitos Humanos e Legislação Participativa (CDH). A fines de 2025 / enero 2026 el Senado desplegó una herramienta de inteligencia artificial (búsqueda semántica) sobre el banco de ideias legislativas (145.993 ideias a enero 2026) que, a pedido de la Consultoria Legislativa cuando un senador prepara un proyecto, busca y selecciona las ideas ciudadanas temáticamente compatibles para incorporarlas y citarlas en la justificación del proyecto de ley, sin exigir el mínimo de apoyos. | G8: Senado Federal de Brasil — Programa e-Cidadania (Secretaria de Transparência / Coordenação do e-Cidadania). El matching de ideias legislativas se opera junto con la Consultoria Legislativa del Senado; herramienta desarrollada por el servidor Alisson Bruno (coordenador do e-Cidadania) en el marco del Desafio de Inovação do Senado. El marcado automático de audiencias corre en el mismo portal e-Cidadania. | H8: Fila FUSIONADA: el MISMO portal e-Cidadania del Senado con DOS aplicaciones de IA — marcado de audiencias (2025, usa LLM) y matching semántico de ideias legislativas (dic-2025 / ene-2026). Cuenta como 1 iniciativa; no volver a separar en dos filas. Confianza ALTA en ambas. | J8: https://www12.senado.leg.br/noticias/materias/2025/03/28/e-cidadania-utiliza-ia-para-marcar-respostas-aos-cidadaos-em-audiencias https://www12.senado.leg.br/noticias/materias/2026/01/16/cidadaos-ajudam-a-escrever-projetos-de-lei-com-ferramenta-de-inteligencia-artificial https://www12.senado.leg.br/radio/1/noticia/2026/01/15/ia-vai-aproximar-ideias-legislativas-do-e-cidadania-e-projetos-de-senadores https://www.poder360.com.br/poder-congresso/ia-do-senado-usa-sugestoes-enviadas-por-cidadaos-em-projetos-de-lei/ | K8: sí | L8: Gobernanza Colaborativa; Participación Digital; Referendos e Iniciativas Populares | M8: Análisis; Traducción Política | N8: 2 | O8: Plataforma | P8: gobierno nacional | Q8: Público | R8: contenido | S8: Gobierno | T8: Nacional | U8: Voz a Texto; LLM; NLP; Búsqueda semántica | V8: sí | W8: =";"&LOWER(SUBSTITUTE(SUBSTITUTE(SUBSTITUTE(L8,"; ",";"),", ",";"),",",";"))&";" -> ;gobernanza colaborativa;participación digital;referendos e iniciativas populares; | X8: =";"&LOWER(SUBSTITUTE(SUBSTITUTE(SUBSTITUTE(M8,"; ",";"),", ",";"),",",";"))&";" -> ;análisis;traducción política; | Y8: =";"&LOWER(SUBSTITUTE(SUBSTITUTE(SUBSTITUTE(P8,"; ",";"),", ",";"),",",";"))&";" -> ;gobierno nacional; | Z8: =";"&LOWER(SUBSTITUTE(SUBSTITUTE(SUBSTITUTE(S8,"; ",";"),", ",";"),",",";"))&";" -> ;gobierno; | AA8: =";"&LOWER(SUBSTITUTE(SUBSTITUTE(SUBSTITUTE(T8,"; ",";"),", ",";"),",",";"))&";" -> ;nacional; | AB8: =";"&LOWER(SUBSTITUTE(SUBSTITUTE(SUBSTITUTE(U8,"; ",";"),", ",";"),",",";"))&";" -> ;voz a texto;llm;nlp;búsqueda semántica; | AC8: =IF(ISNUMBER(SEARCH(";participación digital;",W8)),1,0) -> 1 | AD8: =IF(ISNUMBER(SEARCH(";gobernanza colaborativa;",W8)),1,0) -> 1 | AE8: =IF(ISNUMBER(SEARCH(";mini públicos;",W8)),1,0) -> 0 | AF8: =IF(ISNUMBER(SEARCH(";referendos e iniciativas populares;",W8)),1,0) -> 1 | AG8: =IF(ISNUMBER(SEARCH(";presupuestos participativos;",W8)),1,0) -> 0 | AH8: =IF(ISNUMBER(SEARCH(";planificación;",X8)),1,0) -> 0 | AI8: =IF(ISNUMBER(SEARCH(";implementación;",X8)),1,0) -> 0 | AJ8: =IF(ISNUMBER(SEARCH(";análisis;",X8)),1,0) -> 1 | AK8: =IF(ISNUMBER(SEARCH("traducción",X8)),1,0) -> 1 | AL8: =IF(ISNUMBER(SEARCH(";gobierno local;",Y8)),1,0) -> 0 | AM8: =IF(ISNUMBER(SEARCH(";gobierno nacional;",Y8)),1,0) -> 1 | AN8: =IF(ISNUMBER(SEARCH(";otra institución pública;",Y8)),1,0) -> 0 | AO8: =IF(ISNUMBER(SEARCH(";empresa;",Y8)),1,0) -> 0 | AP8: =IF(ISNUMBER(SEARCH(";universidad;",Y8)),1,0) -> 0 | AQ8: =IF(ISNUMBER(SEARCH(";sociedad civil;",Y8)),1,0) -> 0 | AR8: =IF(ISNUMBER(SEARCH(";organización internacional;",Y8)),1,0) -> 0 | AS8: =IF(ISNUMBER(SEARCH(";privado;",Z8)),1,0) -> 0 | AT8: =IF(ISNUMBER(SEARCH(";academia;",Z8)),1,0) -> 0 | AU8: =IF(ISNUMBER(SEARCH(";gobierno;",Z8)),1,0) -> 1 | AV8: =IF(ISNUMBER(SEARCH(";sociedad civil;",Z8)),1,0) -> 0 | AW8: =IF(ISNUMBER(SEARCH(";nacional;",AA8)),1,0) -> 1 | AX8: =IF(ISNUMBER(SEARCH(";internacional;",AA8)),1,0) -> 0 | AY8: =IF(AND(N8=1,('2 · Índice por país'!$B$25-D8)>'2 · Índice por país'!$B$26),0,N8) -> 2 | AZ8: =IF(SUM(AL8:AR8)<2,"",IF(AL8=1,"GL+","")&IF(AM8=1,"GN+","")&IF(AN8=1,"OIP+","")&IF(AO8=1,"EMP+","")&IF(AP8=1,"UNI+","")&IF(AQ8=1,"SC+","")&IF(AR8=1,"OI+","")) | BA8: =IF(AZ8="",0,IF(COUNTIFS($A$1:$A7,A8,$AZ$1:$AZ7,AZ8)=0,1,0)) -> 0
A9: BR | B9: São Paulo - Programa de Metas 2025-2028 / Participe Mais (Gemini) | C9: BR-sao-paulo-programa-de-metas-participe-ma | D9: 2025 | E9: MEDIA-ALTA | F9: Consulta pública del Programa de Metas 2025-2028 / Plano Plurianual (PPA) 2026-2029 / Planos de Ação das Subprefeituras (PAS) 2026-2029 de la Prefeitura de São Paulo, realizada en el portal Participe Mais (Participe+), plataforma de participación social de la Prefeitura construida sobre el software libre Decidim (basado en CONSUL/Decidim de Madrid-Barcelona). La consulta estuvo abierta del 7/04/2025 al 11/05/2025; el ciclo participativo incluyó 36 audiencias públicas híbridas en la ciudad (abril-mayo 2025) y recibió 6.368 propostas y más de 31.000 interacciones ciudadanas (sugerencias, apoyos, propuestas y críticas). Sobre ese material, en mayo de 2025 Carolina Borges -Agente de Governo Aberto de la Prefeitura- desarrolló una herramienta (Python + Pandas + Google Gemini) que clasifica las propostas en categorías, las ordena por asunto y cantidad de apoyos y genera relatórios y painéis visuales (ranking de temas más recurrentes y participación por distrito y subprefeitura), 'facilitando a divulgação das propostas à população'. La herramienta y su metodología se presentaron en la oficina 'Análise de Dados com Inteligência Artificial na Gestão Pública: Programa de Metas' de la Escola do Parlamento de la Câmara Municipal de São Paulo (15/12/2025), realizada en parceria con el Programa Agentes de Governo Aberto da Prefeitura. | G9: Proceso participativo (Programa de Metas / PPA / PAS): Prefeitura de São Paulo (Secretaria Municipal de Planejamento / Casa Civil / Coordenadoria de Governo Aberto, portal Participe Mais). Herramienta de IA: desarrollada por Carolina Borges, Agente de Governo Aberto de São Paulo (formación en Ciência da Computação y posgrado en Gestão e Controle Social de Políticas Públicas por la Escola de Contas do TCM-SP; experiencia profesional, académica y voluntaria), presentada en la oficina de la Escola do Parlamento da Câmara Municipal de São Paulo en parceria con el Programa Agentes de Governo Aberto. No se confirmó que la Prefeitura adoptara esta herramienta como su pipeline oficial de análisis del proceso. | H9: Confirmar el ESTATUS de la herramienta: la clasificación con Gemini la desarrolló una Agente de Governo Aberto y se presentó en un taller de la Escola do Parlamento; NO se confirmó que la Prefeitura la adoptara como pipeline OFICIAL del proceso. Verificar si es adopción institucional (entra pleno) o iniciativa individual sobre el proceso. | I9: La IA (Gemini) se usa como herramienta de post-procesamiento y análisis exploratorio de datos sobre las propuestas ciudadanas ya recolectadas — no participa en la interacción con el ciudadano, ni en la decisión, sino en clasificar y organizar el volumen de texto libre que la gente ya escribió, para que humanos (técnicos, gestores, la propia población) puedan entender más rápido qué está pidiendo la gente. | J9: https://www.saopaulo.sp.leg.br/escoladoparlamento/cursos/cursos-anteriores/cursos-realizados-em-2025/oficina-analise-de-dados-com-inteligencia-artificial-na-gestao-publica-programa-de-metas/ | K9: sí | L9: Participación Digital; Gobernanza Colaborativa | M9: Análisis | N9: 2 | O9: Uso único | P9: gobierno local | Q9: Público | R9: contenido | S9: Sociedad Civil; Gobierno | T9: Nacional | U9: LLM generativa; NLP; Clasificación de texto | V9: sí | W9: =";"&LOWER(SUBSTITUTE(SUBSTITUTE(SUBSTITUTE(L9,"; ",";"),", ",";"),",",";"))&";" -> ;participación digital;gobernanza colaborativa; | X9: =";"&LOWER(SUBSTITUTE(SUBSTITUTE(SUBSTITUTE(M9,"; ",";"),", ",";"),",",";"))&";" -> ;análisis; | Y9: =";"&LOWER(SUBSTITUTE(SUBSTITUTE(SUBSTITUTE(P9,"; ",";"),", ",";"),",",";"))&";" -> ;gobierno local; | Z9: =";"&LOWER(SUBSTITUTE(SUBSTITUTE(SUBSTITUTE(S9,"; ",";"),", ",";"),",",";"))&";" -> ;sociedad civil;gobierno; | AA9: =";"&LOWER(SUBSTITUTE(SUBSTITUTE(SUBSTITUTE(T9,"; ",";"),", ",";"),",",";"))&";" -> ;nacional; | AB9: =";"&LOWER(SUBSTITUTE(SUBSTITUTE(SUBSTITUTE(U9,"; ",";"),", ",";"),",",";"))&";" -> ;llm generativa;nlp;clasificación de texto; | AC9: =IF(ISNUMBER(SEARCH(";participación digital;",W9)),1,0) -> 1 | AD9: =IF(ISNUMBER(SEARCH(";gobernanza colaborativa;",W9)),1,0) -> 1 | AE9: =IF(ISNUMBER(SEARCH(";mini públicos;",W9)),1,0) -> 0 | AF9: =IF(ISNUMBER(SEARCH(";referendos e iniciativas populares;",W9)),1,0) -> 0 | AG9: =IF(ISNUMBER(SEARCH(";presupuestos participativos;",W9)),1,0) -> 0 | AH9: =IF(ISNUMBER(SEARCH(";planificación;",X9)),1,0) -> 0 | AI9: =IF(ISNUMBER(SEARCH(";implementación;",X9)),1,0) -> 0 | AJ9: =IF(ISNUMBER(SEARCH(";análisis;",X9)),1,0) -> 1 | AK9: =IF(ISNUMBER(SEARCH("traducción",X9)),1,0) -> 0 | AL9: =IF(ISNUMBER(SEARCH(";gobierno local;",Y9)),1,0) -> 1 | AM9: =IF(ISNUMBER(SEARCH(";gobierno nacional;",Y9)),1,0) -> 0 | AN9: =IF(ISNUMBER(SEARCH(";otra institución pública;",Y9)),1,0) -> 0 | AO9: =IF(ISNUMBER(SEARCH(";empresa;",Y9)),1,0) -> 0 | AP9: =IF(ISNUMBER(SEARCH(";universidad;",Y9)),1,0) -> 0 | AQ9: =IF(ISNUMBER(SEARCH(";sociedad civil;",Y9)),1,0) -> 0 | AR9: =IF(ISNUMBER(SEARCH(";organización internacional;",Y9)),1,0) -> 0 | AS9: =IF(ISNUMBER(SEARCH(";privado;",Z9)),1,0) -> 0 | AT9: =IF(ISNUMBER(SEARCH(";academia;",Z9)),1,0) -> 0 | AU9: =IF(ISNUMBER(SEARCH(";gobierno;",Z9)),1,0) -> 1 | AV9: =IF(ISNUMBER(SEARCH(";sociedad civil;",Z9)),1,0) -> 1 | AW9: =IF(ISNUMBER(SEARCH(";nacional;",AA9)),1,0) -> 1 | AX9: =IF(ISNUMBER(SEARCH(";internacional;",AA9)),1,0) -> 0 | AY9: =IF(AND(N9=1,('2 · Índice por país'!$B$25-D9)>'2 · Índice por país'!$B$26),0,N9) -> 2 | AZ9: =IF(SUM(AL9:AR9)<2,"",IF(AL9=1,"GL+","")&IF(AM9=1,"GN+","")&IF(AN9=1,"OIP+","")&IF(AO9=1,"EMP+","")&IF(AP9=1,"UNI+","")&IF(AQ9=1,"SC+","")&IF(AR9=1,"OI+","")) | BA9: =IF(AZ9="",0,IF(COUNTIFS($A$1:$A8,A9,$AZ$1:$AZ8,AZ9)=0,1,0)) -> 0
A10: CL | B10: Cabildos 2016 | C10: CL-cabildos-2016 | D10: 2016 | E10: ALTA (baseline 2025 + reverif. web 2026) | F10: Análisis de los cabildos del proceso constitucional en 2016 | G10: Gobierno de Chile (Presidencia/SEGPRES) — convocante del Proceso Constituyente Abierto; la Biblioteca del Congreso Nacional sistematiza y archiva los resultados (convenio con Senado, Cámara y SEGPRES). | J10: https://www.bcn.cl/procesoconstituyente/cabildos2016/ | K10: sí | L10: Gobernanza Colaborativa | M10: Análisis | N10: 2 | O10: Uso único | P10: gobierno nacional | Q10: Público | R10: contenido | S10: Academia | T10: Nacional | U10: NLP - Tópicos | V10: no | W10: =";"&LOWER(SUBSTITUTE(SUBSTITUTE(SUBSTITUTE(L10,"; ",";"),", ",";"),",",";"))&";" -> ;gobernanza colaborativa; | X10: =";"&LOWER(SUBSTITUTE(SUBSTITUTE(SUBSTITUTE(M10,"; ",";"),", ",";"),",",";"))&";" -> ;análisis; | Y10: =";"&LOWER(SUBSTITUTE(SUBSTITUTE(SUBSTITUTE(P10,"; ",";"),", ",";"),",",";"))&";" -> ;gobierno nacional; | Z10: =";"&LOWER(SUBSTITUTE(SUBSTITUTE(SUBSTITUTE(S10,"; ",";"),", ",";"),",",";"))&";" -> ;academia; | AA10: =";"&LOWER(SUBSTITUTE(SUBSTITUTE(SUBSTITUTE(T10,"; ",";"),", ",";"),",",";"))&";" -> ;nacional; | AB10: =";"&LOWER(SUBSTITUTE(SUBSTITUTE(SUBSTITUTE(U10,"; ",";"),", ",";"),",",";"))&";" -> ;nlp - tópicos; | AC10: =IF(ISNUMBER(SEARCH(";participación digital;",W10)),1,0) -> 0 | AD10: =IF(ISNUMBER(SEARCH(";gobernanza colaborativa;",W10)),1,0) -> 1 | AE10: =IF(ISNUMBER(SEARCH(";mini públicos;",W10)),1,0) -> 0 | AF10: =IF(ISNUMBER(SEARCH(";referendos e iniciativas populares;",W10)),1,0) -> 0 | AG10: =IF(ISNUMBER(SEARCH(";presupuestos participativos;",W10)),1,0) -> 0 | AH10: =IF(ISNUMBER(SEARCH(";planificación;",X10)),1,0) -> 0 | AI10: =IF(ISNUMBER(SEARCH(";implementación;",X10)),1,0) -> 0 | AJ10: =IF(ISNUMBER(SEARCH(";análisis;",X10)),1,0) -> 1 | AK10: =IF(ISNUMBER(SEARCH("traducción",X10)),1,0) -> 0 | AL10: =IF(ISNUMBER(SEARCH(";gobierno local;",Y10)),1,0) -> 0 | AM10: =IF(ISNUMBER(SEARCH(";gobierno nacional;",Y10)),1,0) -> 1 | AN10: =IF(ISNUMBER(SEARCH(";otra institución pública;",Y10)),1,0) -> 0 | AO10: =IF(ISNUMBER(SEARCH(";empresa;",Y10)),1,0) -> 0 | AP10: =IF(ISNUMBER(SEARCH(";universidad;",Y10)),1,0) -> 0 | AQ10: =IF(ISNUMBER(SEARCH(";sociedad civil;",Y10)),1,0) -> 0 | AR10: =IF(ISNUMBER(SEARCH(";organización internacional;",Y10)),1,0) -> 0 | AS10: =IF(ISNUMBER(SEARCH(";privado;",Z10)),1,0) -> 0 | AT10: =IF(ISNUMBER(SEARCH(";academia;",Z10)),1,0) -> 1 | AU10: =IF(ISNUMBER(SEARCH(";gobierno;",Z10)),1,0) -> 0 | AV10: =IF(ISNUMBER(SEARCH(";sociedad civil;",Z10)),1,0) -> 0 | AW10: =IF(ISNUMBER(SEARCH(";nacional;",AA10)),1,0) -> 1 | AX10: =IF(ISNUMBER(SEARCH(";internacional;",AA10)),1,0) -> 0 | AY10: =IF(AND(N10=1,('2 · Índice por país'!$B$25-D10)>'2 · Índice por país'!$B$26),0,N10) -> 2 | AZ10: =IF(SUM(AL10:AR10)<2,"",IF(AL10=1,"GL+","")&IF(AM10=1,"GN+","")&IF(AN10=1,"OIP+","")&IF(AO10=1,"EMP+","")&IF(AP10=1,"UNI+","")&IF(AQ10=1,"SC+","")&IF(AR10=1,"OI+","")) | BA10: =IF(AZ10="",0,IF(COUNTIFS($A$1:$A9,A10,$AZ$1:$AZ9,AZ10)=0,1,0)) -> 0
A11: CL | B11: El Chile que Queremos (ECQQ) - MinCiencia | C11: CL-el-chile-que-queremos-ecqq-minciencia | D11: 2019 | E11: ALTA | F11: Iniciativa gubernamental de diálogos ciudadanos y escucha social presentada por el Gobierno de Chile el 22 de noviembre de 2019, en el marco del Acuerdo por la Justicia Social y el Acuerdo por una Nueva Constitución tras el estallido social. Entre noviembre de 2019 y marzo de 2020, la ciudadanía pudo participar mediante diálogos grupales (cabildos) o consultas individuales en el sitio www.chilequequeremos.cl, registrando sus necesidades y propuestas para complementar futuras políticas públicas. El proceso fue un esfuerzo conjunto de los Ministerios de Desarrollo Social y Familia, de Ciencia/Tecnología/Conocimiento e Innovación (MinCiencia), de Agricultura, la SEGEGOB y la División de Gobierno Digital. El Ministerio de Ciencia fue responsable de SISTEMATIZAR los aportes ciudadanos usando ciencia de datos / IA: el repositorio público MinCiencia/ECQQ contiene el código que clasifica las contribuciones (texto libre de los aportes) mediante redes neuronales recurrentes (RNN) y árboles de decisión (Random Forest), y sistematiza emociones y necesidades mediante análisis de tópicos (NLP/LDA) sobre el contenido de diálogos y consultas individuales. | G11: Gobierno de Chile - proceso conjunto liderado por el Ministerio de Desarrollo Social y Familia; sistematización de los aportes con ciencia de datos/IA a cargo del Ministerio de Ciencia, Tecnología, Conocimiento e Innovación (MinCiencia). Participaron también Ministerio de Agricultura, SEGEGOB y División de Gobierno Digital. | J11: https://github.com/MinCiencia/ECQQ | K11: sí | L11: Participación Digital; Gobernanza Colaborativa | M11: Análisis | N11: 2 | O11: Uso único | P11: gobierno nacional | Q11: Público | R11: contenido | S11: Gobierno | T11: Nacional | U11: NLP; Clasificación de texto; Modelado de tópicos (LDA); Redes neuronales recurrentes (RNN); Random Forest; Clasificación de emociones; Machine Learning | V11: no | W11: =";"&LOWER(SUBSTITUTE(SUBSTITUTE(SUBSTITUTE(L11,"; ",";"),", ",";"),",",";"))&";" -> ;participación digital;gobernanza colaborativa; | X11: =";"&LOWER(SUBSTITUTE(SUBSTITUTE(SUBSTITUTE(M11,"; ",";"),", ",";"),",",";"))&";" -> ;análisis; | Y11: =";"&LOWER(SUBSTITUTE(SUBSTITUTE(SUBSTITUTE(P11,"; ",";"),", ",";"),",",";"))&";" -> ;gobierno nacional; | Z11: =";"&LOWER(SUBSTITUTE(SUBSTITUTE(SUBSTITUTE(S11,"; ",";"),", ",";"),",",";"))&";" -> ;gobierno; | AA11: =";"&LOWER(SUBSTITUTE(SUBSTITUTE(SUBSTITUTE(T11,"; ",";"),", ",";"),",",";"))&";" -> ;nacional; | AB11: =";"&LOWER(SUBSTITUTE(SUBSTITUTE(SUBSTITUTE(U11,"; ",";"),", ",";"),",",";"))&";" -> ;nlp;clasificación de texto;modelado de tópicos (lda);redes neuronales recurrentes (rnn);random forest;clasificación de emociones;machine learning; | AC11: =IF(ISNUMBER(SEARCH(";participación digital;",W11)),1,0) -> 1 | AD11: =IF(ISNUMBER(SEARCH(";gobernanza colaborativa;",W11)),1,0) -> 1 | AE11: =IF(ISNUMBER(SEARCH(";mini públicos;",W11)),1,0) -> 0 | AF11: =IF(ISNUMBER(SEARCH(";referendos e iniciativas populares;",W11)),1,0) -> 0 | AG11: =IF(ISNUMBER(SEARCH(";presupuestos participativos;",W11)),1,0) -> 0 | AH11: =IF(ISNUMBER(SEARCH(";planificación;",X11)),1,0) -> 0 | AI11: =IF(ISNUMBER(SEARCH(";implementación;",X11)),1,0) -> 0 | AJ11: =IF(ISNUMBER(SEARCH(";análisis;",X11)),1,0) -> 1 | AK11: =IF(ISNUMBER(SEARCH("traducción",X11)),1,0) -> 0 | AL11: =IF(ISNUMBER(SEARCH(";gobierno local;",Y11)),1,0) -> 0 | AM11: =IF(ISNUMBER(SEARCH(";gobierno nacional;",Y11)),1,0) -> 1 | AN11: =IF(ISNUMBER(SEARCH(";otra institución pública;",Y11)),1,0) -> 0 | AO11: =IF(ISNUMBER(SEARCH(";empresa;",Y11)),1,0) -> 0 | AP11: =IF(ISNUMBER(SEARCH(";universidad;",Y11)),1,0) -> 0 | AQ11: =IF(ISNUMBER(SEARCH(";sociedad civil;",Y11)),1,0) -> 0 | AR11: =IF(ISNUMBER(SEARCH(";organización internacional;",Y11)),1,0) -> 0 | AS11: =IF(ISNUMBER(SEARCH(";privado;",Z11)),1,0) -> 0 | AT11: =IF(ISNUMBER(SEARCH(";academia;",Z11)),1,0) -> 0 | AU11: =IF(ISNUMBER(SEARCH(";gobierno;",Z11)),1,0) -> 1 | AV11: =IF(ISNUMBER(SEARCH(";sociedad civil;",Z11)),1,0) -> 0 | AW11: =IF(ISNUMBER(SEARCH(";nacional;",AA11)),1,0) -> 1 | AX11: =IF(ISNUMBER(SEARCH(";internacional;",AA11)),1,0) -> 0 | AY11: =IF(AND(N11=1,('2 · Índice por país'!$B$25-D11)>'2 · Índice por país'!$B$26),0,N11) -> 2 | AZ11: =IF(SUM(AL11:AR11)<2,"",IF(AL11=1,"GL+","")&IF(AM11=1,"GN+","")&IF(AN11=1,"OIP+","")&IF(AO11=1,"EMP+","")&IF(AP11=1,"UNI+","")&IF(AQ11=1,"SC+","")&IF(AR11=1,"OI+","")) | BA11: =IF(AZ11="",0,IF(COUNTIFS($A$1:$A10,A11,$AZ$1:$AZ10,AZ11)=0,1,0)) -> 0
A12: CL | B12: Estudio dIAlogos - Percepciones de Futuro | C12: CL-estudio-dialogos-percepciones-de-futuro | D12: 2021 | E12: MEDIA (baseline 2025; sin señal web 2026 nueva) | F12: Estudio que utilizó distintas herramientas de IA para conocer las percepciones de futuro de la población chilena | G12: Fundación Encuentros del Futuro y Merlín Research | I12: Ajuste link | J12: https://fairlac.iadb.org/en/dialogos-study-perceptions-future | K12: sí | L12: Gobernanza Colaborativa | M12: Implementación; Análisis | N12: 2 | O12: Uso único | P12: sociedad civil; empresa | Q12: Mixto | R12: contenido | S12: Privado | T12: Nacional | U12: NLP | V12: no | W12: =";"&LOWER(SUBSTITUTE(SUBSTITUTE(SUBSTITUTE(L12,"; ",";"),", ",";"),",",";"))&";" -> ;gobernanza colaborativa; | X12: =";"&LOWER(SUBSTITUTE(SUBSTITUTE(SUBSTITUTE(M12,"; ",";"),", ",";"),",",";"))&";" -> ;implementación;análisis; | Y12: =";"&LOWER(SUBSTITUTE(SUBSTITUTE(SUBSTITUTE(P12,"; ",";"),", ",";"),",",";"))&";" -> ;sociedad civil;empresa; | Z12: =";"&LOWER(SUBSTITUTE(SUBSTITUTE(SUBSTITUTE(S12,"; ",";"),", ",";"),",",";"))&";" -> ;privado; | AA12: =";"&LOWER(SUBSTITUTE(SUBSTITUTE(SUBSTITUTE(T12,"; ",";"),", ",";"),",",";"))&";" -> ;nacional; | AB12: =";"&LOWER(SUBSTITUTE(SUBSTITUTE(SUBSTITUTE(U12,"; ",";"),", ",";"),",",";"))&";" -> ;nlp; | AC12: =IF(ISNUMBER(SEARCH(";participación digital;",W12)),1,0) -> 0 | AD12: =IF(ISNUMBER(SEARCH(";gobernanza colaborativa;",W12)),1,0) -> 1 | AE12: =IF(ISNUMBER(SEARCH(";mini públicos;",W12)),1,0) -> 0 | AF12: =IF(ISNUMBER(SEARCH(";referendos e iniciativas populares;",W12)),1,0) -> 0 | AG12: =IF(ISNUMBER(SEARCH(";presupuestos participativos;",W12)),1,0) -> 0 | AH12: =IF(ISNUMBER(SEARCH(";planificación;",X12)),1,0) -> 0 | AI12: =IF(ISNUMBER(SEARCH(";implementación;",X12)),1,0) -> 1 | AJ12: =IF(ISNUMBER(SEARCH(";análisis;",X12)),1,0) -> 1 | AK12: =IF(ISNUMBER(SEARCH("traducción",X12)),1,0) -> 0 | AL12: =IF(ISNUMBER(SEARCH(";gobierno local;",Y12)),1,0) -> 0 | AM12: =IF(ISNUMBER(SEARCH(";gobierno nacional;",Y12)),1,0) -> 0 | AN12: =IF(ISNUMBER(SEARCH(";otra institución pública;",Y12)),1,0) -> 0 | AO12: =IF(ISNUMBER(SEARCH(";empresa;",Y12)),1,0) -> 1 | AP12: =IF(ISNUMBER(SEARCH(";universidad;",Y12)),1,0) -> 0 | AQ12: =IF(ISNUMBER(SEARCH(";sociedad civil;",Y12)),1,0) -> 1 | AR12: =IF(ISNUMBER(SEARCH(";organización internacional;",Y12)),1,0) -> 0 | AS12: =IF(ISNUMBER(SEARCH(";privado;",Z12)),1,0) -> 1 | AT12: =IF(ISNUMBER(SEARCH(";academia;",Z12)),1,0) -> 0 | AU12: =IF(ISNUMBER(SEARCH(";gobierno;",Z12)),1,0) -> 0 | AV12: =IF(ISNUMBER(SEARCH(";sociedad civil;",Z12)),1,0) -> 0 | AW12: =IF(ISNUMBER(SEARCH(";nacional;",AA12)),1,0) -> 1 | AX12: =IF(ISNUMBER(SEARCH(";internacional;",AA12)),1,0) -> 0 | AY12: =IF(AND(N12=1,('2 · Índice por país'!$B$25-D12)>'2 · Índice por país'!$B$26),0,N12) -> 2 | AZ12: =IF(SUM(AL12:AR12)<2,"",IF(AL12=1,"GL+","")&IF(AM12=1,"GN+","")&IF(AN12=1,"OIP+","")&IF(AO12=1,"EMP+","")&IF(AP12=1,"UNI+","")&IF(AQ12=1,"SC+","")&IF(AR12=1,"OI+","")) -> EMP+SC+ | BA12: =IF(AZ12="",0,IF(COUNTIFS($A$1:$A11,A12,$AZ$1:$AZ11,AZ12)=0,1,0)) -> 1
A13: CL | B13: Jornada de Escucha Lanzamiento Instituto de Políticas Públicas UNAB | C13: CL-jornada-de-escucha-lanzamiento-instituto | D13: 2022 | E13: MEDIA (baseline 2025; sin señal web 2026 nueva) | F13: Jornadas de diálogo de la comunidad académica y otos stakeholders. | G13: Universidad Andres Bello | J13: https://ipp.unab.cl/ https://public.tableau.com/app/profile/ivania.yovanovic/viz/JornadasInstitutoPolticasPblicasUNAB/Dashboard3 | K13: sí | L13: Gobernanza Colaborativa | M13: Análisis | N13: 2 | O13: Uso único | P13: universidad | Q13: Privado | R13: contenido | S13: Privado | T13: Nacional | U13: NLP - Tópicos | V13: no | W13: =";"&LOWER(SUBSTITUTE(SUBSTITUTE(SUBSTITUTE(L13,"; ",";"),", ",";"),",",";"))&";" -> ;gobernanza colaborativa; | X13: =";"&LOWER(SUBSTITUTE(SUBSTITUTE(SUBSTITUTE(M13,"; ",";"),", ",";"),",",";"))&";" -> ;análisis; | Y13: =";"&LOWER(SUBSTITUTE(SUBSTITUTE(SUBSTITUTE(P13,"; ",";"),", ",";"),",",";"))&";" -> ;universidad; | Z13: =";"&LOWER(SUBSTITUTE(SUBSTITUTE(SUBSTITUTE(S13,"; ",";"),", ",";"),",",";"))&";" -> ;privado; | AA13: =";"&LOWER(SUBSTITUTE(SUBSTITUTE(SUBSTITUTE(T13,"; ",";"),", ",";"),",",";"))&";" -> ;nacional; | AB13: =";"&LOWER(SUBSTITUTE(SUBSTITUTE(SUBSTITUTE(U13,"; ",";"),", ",";"),",",";"))&";" -> ;nlp - tópicos; | AC13: =IF(ISNUMBER(SEARCH(";participación digital;",W13)),1,0) -> 0 | AD13: =IF(ISNUMBER(SEARCH(";gobernanza colaborativa;",W13)),1,0) -> 1 | AE13: =IF(ISNUMBER(SEARCH(";mini públicos;",W13)),1,0) -> 0 | AF13: =IF(ISNUMBER(SEARCH(";referendos e iniciativas populares;",W13)),1,0) -> 0 | AG13: =IF(ISNUMBER(SEARCH(";presupuestos participativos;",W13)),1,0) -> 0 | AH13: =IF(ISNUMBER(SEARCH(";planificación;",X13)),1,0) -> 0 | AI13: =IF(ISNUMBER(SEARCH(";implementación;",X13)),1,0) -> 0 | AJ13: =IF(ISNUMBER(SEARCH(";análisis;",X13)),1,0) -> 1 | AK13: =IF(ISNUMBER(SEARCH("traducción",X13)),1,0) -> 0 | AL13: =IF(ISNUMBER(SEARCH(";gobierno local;",Y13)),1,0) -> 0 | AM13: =IF(ISNUMBER(SEARCH(";gobierno nacional;",Y13)),1,0) -> 0 | AN13: =IF(ISNUMBER(SEARCH(";otra institución pública;",Y13)),1,0) -> 0 | AO13: =IF(ISNUMBER(SEARCH(";empresa;",Y13)),1,0) -> 0 | AP13: =IF(ISNUMBER(SEARCH(";universidad;",Y13)),1,0) -> 1 | AQ13: =IF(ISNUMBER(SEARCH(";sociedad civil;",Y13)),1,0) -> 0 | AR13: =IF(ISNUMBER(SEARCH(";organización internacional;",Y13)),1,0) -> 0 | AS13: =IF(ISNUMBER(SEARCH(";privado;",Z13)),1,0) -> 1 | AT13: =IF(ISNUMBER(SEARCH(";academia;",Z13)),1,0) -> 0 | AU13: =IF(ISNUMBER(SEARCH(";gobierno;",Z13)),1,0) -> 0 | AV13: =IF(ISNUMBER(SEARCH(";sociedad civil;",Z13)),1,0) -> 0 | AW13: =IF(ISNUMBER(SEARCH(";nacional;",AA13)),1,0) -> 1 | AX13: =IF(ISNUMBER(SEARCH(";internacional;",AA13)),1,0) -> 0 | AY13: =IF(AND(N13=1,('2 · Índice por país'!$B$25-D13)>'2 · Índice por país'!$B$26),0,N13) -> 2 | AZ13: =IF(SUM(AL13:AR13)<2,"",IF(AL13=1,"GL+","")&IF(AM13=1,"GN+","")&IF(AN13=1,"OIP+","")&IF(AO13=1,"EMP+","")&IF(AP13=1,"UNI+","")&IF(AQ13=1,"SC+","")&IF(AR13=1,"OI+","")) | BA13: =IF(AZ13="",0,IF(COUNTIFS($A$1:$A12,A13,$AZ$1:$AZ12,AZ13)=0,1,0)) -> 0
A14: CL | B14: LXS 400 - Chile Delibera | C14: CL-lxs-400-chile-delibera | D14: 2020 | E14: ALTA | F14: Encuesta deliberativa nacional (Deliberative Poll, modelo de James S. Fishkin) convocada por el Senado de Chile (Comisión Desafíos del Futuro) junto a la Fundación Tribu, el Centro para la Democracia Deliberativa de la Universidad de Stanford, la Universidad de Chile, la Asociación Chilena de Municipalidades (AChM) y el Servicio de Registro Civil. Un mini-público de ~400-514 ciudadanos seleccionados aleatoriamente y representativos del país deliberó de forma online (vía Zoom y la Stanford Online Deliberation Platform) los días 5, 6 y 7 de marzo de 2021 sobre reformas a pensiones y salud, en grupos pequeños y sesiones plenarias, de cara al debate constitucional. El proceso comenzó en diciembre de 2020 con la selección de la muestra y la entrega de material informativo equilibrado (argumentos a favor y en contra). La plataforma online de Stanford incorporó un moderador automatizado (IA) que controlaba los tiempos y distribuía equitativamente los turnos de palabra (colas de habla, temporizador, sistema de señal para determinar quién hablaba a continuación); en paralelo, el Centro de Microdatos de la U. de Chile usó tecnología basada en IA para seleccionar la muestra representativa. | G14: Senado de Chile (Comisión Desafíos del Futuro, Ciencia, Tecnología e Innovación) y Fundación Tribu, con la Universidad de Stanford (Center for Deliberative Democracy / Deliberative Democracy Lab), la Universidad de Chile (Centro de Microdatos), la Asociación Chilena de Municipalidades (AChM) y el Servicio de Registro Civil e Identificación. | I14: La primera semana de abril se espera que los organizadores entreguen un informe cuantitativo, uno cualitativo, otro de Inteligencia Artificial (IA) y una propuesta de políticas públicas. | J14: https://es.wikipedia.org/wiki/Lxs_400:_Chile_Delibera https://www.senado.cl/comunicaciones/noticias/chile-delibera-lxs-400-un-fin-de-semana-de-democracia-deliberativa-online | K14: sí | L14: Mini públicos | M14: Implementación; Planificación | N14: 2 | O14: Uso único | P14: gobierno nacional; universidad; sociedad civil | Q14: Mixto | R14: apoyo | S14: Academia | T14: Internacional | U14: Moderación/facilitación automatizada; Sistema de reglas/temporización; Muestreo estadístico asistido por IA | V14: no | W14: =";"&LOWER(SUBSTITUTE(SUBSTITUTE(SUBSTITUTE(L14,"; ",";"),", ",";"),",",";"))&";" -> ;mini públicos; | X14: =";"&LOWER(SUBSTITUTE(SUBSTITUTE(SUBSTITUTE(M14,"; ",";"),", ",";"),",",";"))&";" -> ;implementación;planificación; | Y14: =";"&LOWER(SUBSTITUTE(SUBSTITUTE(SUBSTITUTE(P14,"; ",";"),", ",";"),",",";"))&";" -> ;gobierno nacional;universidad;sociedad civil; | Z14: =";"&LOWER(SUBSTITUTE(SUBSTITUTE(SUBSTITUTE(S14,"; ",";"),", ",";"),",",";"))&";" -> ;academia; | AA14: =";"&LOWER(SUBSTITUTE(SUBSTITUTE(SUBSTITUTE(T14,"; ",";"),", ",";"),",",";"))&";" -> ;internacional; | AB14: =";"&LOWER(SUBSTITUTE(SUBSTITUTE(SUBSTITUTE(U14,"; ",";"),", ",";"),",",";"))&";" -> ;moderación/facilitación automatizada;sistema de reglas/temporización;muestreo estadístico asistido por ia; | AC14: =IF(ISNUMBER(SEARCH(";participación digital;",W14)),1,0) -> 0 | AD14: =IF(ISNUMBER(SEARCH(";gobernanza colaborativa;",W14)),1,0) -> 0 | AE14: =IF(ISNUMBER(SEARCH(";mini públicos;",W14)),1,0) -> 1 | AF14: =IF(ISNUMBER(SEARCH(";referendos e iniciativas populares;",W14)),1,0) -> 0 | AG14: =IF(ISNUMBER(SEARCH(";presupuestos participativos;",W14)),1,0) -> 0 | AH14: =IF(ISNUMBER(SEARCH(";planificación;",X14)),1,0) -> 1 | AI14: =IF(ISNUMBER(SEARCH(";implementación;",X14)),1,0) -> 1 | AJ14: =IF(ISNUMBER(SEARCH(";análisis;",X14)),1,0) -> 0 | AK14: =IF(ISNUMBER(SEARCH("traducción",X14)),1,0) -> 0 | AL14: =IF(ISNUMBER(SEARCH(";gobierno local;",Y14)),1,0) -> 0 | AM14: =IF(ISNUMBER(SEARCH(";gobierno nacional;",Y14)),1,0) -> 1 | AN14: =IF(ISNUMBER(SEARCH(";otra institución pública;",Y14)),1,0) -> 0 | AO14: =IF(ISNUMBER(SEARCH(";empresa;",Y14)),1,0) -> 0 | AP14: =IF(ISNUMBER(SEARCH(";universidad;",Y14)),1,0) -> 1 | AQ14: =IF(ISNUMBER(SEARCH(";sociedad civil;",Y14)),1,0) -> 1 | AR14: =IF(ISNUMBER(SEARCH(";organización internacional;",Y14)),1,0) -> 0 | AS14: =IF(ISNUMBER(SEARCH(";privado;",Z14)),1,0) -> 0 | AT14: =IF(ISNUMBER(SEARCH(";academia;",Z14)),1,0) -> 1 | AU14: =IF(ISNUMBER(SEARCH(";gobierno;",Z14)),1,0) -> 0 | AV14: =IF(ISNUMBER(SEARCH(";sociedad civil;",Z14)),1,0) -> 0 | AW14: =IF(ISNUMBER(SEARCH(";nacional;",AA14)),1,0) -> 0 | AX14: =IF(ISNUMBER(SEARCH(";internacional;",AA14)),1,0) -> 1 | AY14: =IF(AND(N14=1,('2 · Índice por país'!$B$25-D14)>'2 · Índice por país'!$B$26),0,N14) -> 2 | AZ14: =IF(SUM(AL14:AR14)<2,"",IF(AL14=1,"GL+","")&IF(AM14=1,"GN+","")&IF(AN14=1,"OIP+","")&IF(AO14=1,"EMP+","")&IF(AP14=1,"UNI+","")&IF(AQ14=1,"SC+","")&IF(AR14=1,"OI+","")) -> GN+UNI+SC+ | BA14: =IF(AZ14="",0,IF(COUNTIFS($A$1:$A13,A14,$AZ$1:$AZ13,AZ14)=0,1,0)) -> 1
A15: CL | B15: La voz de los nuevos votantes | C15: CL-la-voz-de-los-nuevos-votantes | D15: 2023 | E15: MEDIA (baseline 2025; sin señal web 2026 nueva) | F15: Análisis de Lenguaje Natural para los audios transcritos de encuesta realizada en persona. | G15: Universidad Andres Bello | J15: https://ipp.unab.cl/wp-content/uploads/2023/10/2-IPP-UNAB_Informe-Voz-de-los-votantes.pdf https://ipp.unab.cl/publicacion/la-voz-de-los-nuevos-votantes-san-bernardo/ | K15: sí | L15: Gobernanza Colaborativa | M15: Implementación; Análisis | N15: 2 | O15: Uso único | P15: universidad | Q15: Privado | R15: contenido | S15: Privado | T15: Nacional | U15: NLP - Tópicos | V15: no | W15: =";"&LOWER(SUBSTITUTE(SUBSTITUTE(SUBSTITUTE(L15,"; ",";"),", ",";"),",",";"))&";" -> ;gobernanza colaborativa; | X15: =";"&LOWER(SUBSTITUTE(SUBSTITUTE(SUBSTITUTE(M15,"; ",";"),", ",";"),",",";"))&";" -> ;implementación;análisis; | Y15: =";"&LOWER(SUBSTITUTE(SUBSTITUTE(SUBSTITUTE(P15,"; ",";"),", ",";"),",",";"))&";" -> ;universidad; | Z15: =";"&LOWER(SUBSTITUTE(SUBSTITUTE(SUBSTITUTE(S15,"; ",";"),", ",";"),",",";"))&";" -> ;privado; | AA15: =";"&LOWER(SUBSTITUTE(SUBSTITUTE(SUBSTITUTE(T15,"; ",";"),", ",";"),",",";"))&";" -> ;nacional; | AB15: =";"&LOWER(SUBSTITUTE(SUBSTITUTE(SUBSTITUTE(U15,"; ",";"),", ",";"),",",";"))&";" -> ;nlp - tópicos; | AC15: =IF(ISNUMBER(SEARCH(";participación digital;",W15)),1,0) -> 0 | AD15: =IF(ISNUMBER(SEARCH(";gobernanza colaborativa;",W15)),1,0) -> 1 | AE15: =IF(ISNUMBER(SEARCH(";mini públicos;",W15)),1,0) -> 0 | AF15: =IF(ISNUMBER(SEARCH(";referendos e iniciativas populares;",W15)),1,0) -> 0 | AG15: =IF(ISNUMBER(SEARCH(";presupuestos participativos;",W15)),1,0) -> 0 | AH15: =IF(ISNUMBER(SEARCH(";planificación;",X15)),1,0) -> 0 | AI15: =IF(ISNUMBER(SEARCH(";implementación;",X15)),1,0) -> 1 | AJ15: =IF(ISNUMBER(SEARCH(";análisis;",X15)),1,0) -> 1 | AK15: =IF(ISNUMBER(SEARCH("traducción",X15)),1,0) -> 0 | AL15: =IF(ISNUMBER(SEARCH(";gobierno local;",Y15)),1,0) -> 0 | AM15: =IF(ISNUMBER(SEARCH(";gobierno nacional;",Y15)),1,0) -> 0 | AN15: =IF(ISNUMBER(SEARCH(";otra institución pública;",Y15)),1,0) -> 0 | AO15: =IF(ISNUMBER(SEARCH(";empresa;",Y15)),1,0) -> 0 | AP15: =IF(ISNUMBER(SEARCH(";universidad;",Y15)),1,0) -> 1 | AQ15: =IF(ISNUMBER(SEARCH(";sociedad civil;",Y15)),1,0) -> 0 | AR15: =IF(ISNUMBER(SEARCH(";organización internacional;",Y15)),1,0) -> 0 | AS15: =IF(ISNUMBER(SEARCH(";privado;",Z15)),1,0) -> 1 | AT15: =IF(ISNUMBER(SEARCH(";academia;",Z15)),1,0) -> 0 | AU15: =IF(ISNUMBER(SEARCH(";gobierno;",Z15)),1,0) -> 0 | AV15: =IF(ISNUMBER(SEARCH(";sociedad civil;",Z15)),1,0) -> 0 | AW15: =IF(ISNUMBER(SEARCH(";nacional;",AA15)),1,0) -> 1 | AX15: =IF(ISNUMBER(SEARCH(";internacional;",AA15)),1,0) -> 0 | AY15: =IF(AND(N15=1,('2 · Índice por país'!$B$25-D15)>'2 · Índice por país'!$B$26),0,N15) -> 2 | AZ15: =IF(SUM(AL15:AR15)<2,"",IF(AL15=1,"GL+","")&IF(AM15=1,"GN+","")&IF(AN15=1,"OIP+","")&IF(AO15=1,"EMP+","")&IF(AP15=1,"UNI+","")&IF(AQ15=1,"SC+","")&IF(AR15=1,"OI+","")) | BA15: =IF(AZ15="",0,IF(COUNTIFS($A$1:$A14,A15,$AZ$1:$AZ14,AZ15)=0,1,0)) -> 0
