Workbook

Sheet 1 · BBDD 2025 (insumo)
A1: País | B1: Caso | C1: Año | D1: Descripción breve | E1: Organización a cargo | F1: Tipo de Organización (2025) | G1: Tipo de Proceso | H1: Etapa de Participación | I1: Continuidad (2025) | J1: Tipo de Desarrollador | K1: Origen Desarrollador | L1: Tipos de IA (2025) | M1: Convocante 7-cat (recodificación 2026, BORRADOR) | N1: Nivel 0-3 (recodificación 2026, override aplicado) | O1: Nota recodificación | P1: norm proceso | Q1: norm etapa | R1: norm desarrollador | S1: norm origen | T1: norm sistemas IA | U1: norm convocante | V1: TP: Participación Digital (0/1) | W1: TP: Gobernanza Colaborativa (0/1) | X1: TP: Mini públicos (0/1) | Y1: TP: Referendos e Inic. Populares (0/1) | Z1: TP: Presupuestos Participativos (0/1) | AA1: ET: Planificación (0/1) | AB1: ET: Implementación (0/1) | AC1: ET: Análisis (0/1) | AD1: ET: Traducción Política (0/1) | AE1: ORG: Público (0/1) | AF1: ORG: Privado (0/1) | AG1: ORG: Mixto (0/1) | AH1: CONT: Uso único (0/1) | AI1: CONT: Plataforma (0/1) | AJ1: DEV: Industria (0/1) | AK1: DEV: Academia (0/1) | AL1: DEV: Gobierno (0/1) | AM1: DEV: Sociedad Civil (0/1) | AN1: ORIGEN: Nacional (0/1) | AO1: ORIGEN: Internacional (0/1) | AP1: CONV: gobierno local (0/1) | AQ1: CONV: gobierno nacional (0/1) | AR1: CONV: otra institución pública (0/1) | AS1: CONV: empresa (0/1) | AT1: CONV: universidad (0/1) | AU1: CONV: sociedad civil (0/1) | AV1: CONV: organización internacional (0/1) | AW1: Nivel efectivo | AX1: Clave combinación convocantes | AY1: Combinación 1ª aparición (país)
A2: BO | B2: Bolivia Conversa | C2: 2021 | D2: Plataforma de diálogo digital que emplea IA para procesar y agrupar aportaciones ciudadanas en tiempo real, retornando feedback inmediato y garantizando anonimato, con vistas a fomentar el reencuentro y la cohesión social en el país. | E2: Vicepresidencia del Estado Plurinacional de Bolivia y Sistema de Naciones Unidas en Bolivia | F2: Público | G2: Governanza Colaborativa | H2: Implementación, Análisis | I2: Uso único | J2: Gobierno | K2: Internacional | L2: NLP - Tópicos | M2: gobierno nacional; organización internacional | N2: 2 | P2: =";"&LOWER(SUBSTITUTE(SUBSTITUTE(SUBSTITUTE(G2,"; ",";"),", ",";"),",",";"))&";" -> ;governanza colaborativa; | Q2: =";"&LOWER(SUBSTITUTE(SUBSTITUTE(SUBSTITUTE(H2,"; ",";"),", ",";"),",",";"))&";" -> ;implementación;análisis; | R2: =";"&LOWER(SUBSTITUTE(SUBSTITUTE(SUBSTITUTE(J2,"; ",";"),", ",";"),",",";"))&";" -> ;gobierno; | S2: =";"&LOWER(SUBSTITUTE(SUBSTITUTE(SUBSTITUTE(K2,"; ",";"),", ",";"),",",";"))&";" -> ;internacional; | T2: =";"&LOWER(SUBSTITUTE(SUBSTITUTE(SUBSTITUTE(L2,"; ",";"),", ",";"),",",";"))&";" -> ;nlp - tópicos; | U2: =";"&LOWER(SUBSTITUTE(SUBSTITUTE(SUBSTITUTE(M2,"; ",";"),", ",";"),",",";"))&";" -> ;gobierno nacional;organización internacional; | V2: =IF(ISNUMBER(SEARCH(";participación digital;",P2)),1,0) -> 0 | W2: =IF(OR(ISNUMBER(SEARCH(";governanza colaborativa;",P2)),ISNUMBER(SEARCH(";gobernanza colaborativa;",P2))),1,0) -> 1 | X2: =IF(ISNUMBER(SEARCH(";mini públicos;",P2)),1,0) -> 0 | Y2: =IF(ISNUMBER(SEARCH(";referendos e iniciativas populares;",P2)),1,0) -> 0 | Z2: =IF(ISNUMBER(SEARCH(";presupuestos participativos;",P2)),1,0) -> 0 | AA2: =IF(ISNUMBER(SEARCH("planif",Q2)),1,0) -> 0 | AB2: =IF(ISNUMBER(SEARCH("implement",Q2)),1,0) -> 1 | AC2: =IF(ISNUMBER(SEARCH("análisis",Q2)),1,0) -> 1 | AD2: =IF(ISNUMBER(SEARCH("traducción",Q2)),1,0) -> 0 | AE2: =IF(ISNUMBER(SEARCH("público",F2)),1,0) -> 1 | AF2: =IF(ISNUMBER(SEARCH("privado",F2)),1,0) -> 0 | AG2: =IF(ISNUMBER(SEARCH("mixto",F2)),1,0) -> 0 | AH2: =IF(ISNUMBER(SEARCH("único",I2)),1,0) -> 1 | AI2: =IF(ISNUMBER(SEARCH("plataforma",I2)),1,0) -> 0 | AJ2: =IF(ISNUMBER(SEARCH(";industria;",R2)),1,0) -> 0 | AK2: =IF(ISNUMBER(SEARCH(";academia;",R2)),1,0) -> 0 | AL2: =IF(ISNUMBER(SEARCH(";gobierno;",R2)),1,0) -> 1 | AM2: =IF(ISNUMBER(SEARCH(";sociedad civil;",R2)),1,0) -> 0 | AN2: =IF(ISNUMBER(SEARCH(";nacional;",S2)),1,0) -> 0 | AO2: =IF(ISNUMBER(SEARCH(";internacional;",S2)),1,0) -> 1 | AP2: =IF(ISNUMBER(SEARCH(";gobierno local;",U2)),1,0) -> 0 | AQ2: =IF(ISNUMBER(SEARCH(";gobierno nacional;",U2)),1,0) -> 1 | AR2: =IF(ISNUMBER(SEARCH(";otra institución pública;",U2)),1,0) -> 0 | AS2: =IF(ISNUMBER(SEARCH(";empresa;",U2)),1,0) -> 0 | AT2: =IF(ISNUMBER(SEARCH(";universidad;",U2)),1,0) -> 0 | AU2: =IF(ISNUMBER(SEARCH(";sociedad civil;",U2)),1,0) -> 0 | AV2: =IF(ISNUMBER(SEARCH(";organización internacional;",U2)),1,0) -> 1 | AW2: =IF(N2="","",IF(AND(N2=1,('3 · Cálculo 2025 · f. nueva'!$C$25-C2)>'3 · Cálculo 2025 · f. nueva'!$C$26),0,N2)) -> 2 | AX2: =IF(SUM(AP2:AV2)<2,"",IF(AP2=1,"GL+","")&IF(AQ2=1,"GN+","")&IF(AR2=1,"OIP+","")&IF(AS2=1,"EMP+","")&IF(AT2=1,"UNI+","")&IF(AU2=1,"SC+","")&IF(AV2=1,"OI+","")) -> GN+OI+ | AY2: =IF(AX2="",0,IF(COUNTIFS($A$1:A1,A2,$AX$1:AX1,AX2)=0,1,0)) -> 1
A3: BR | B3: Portal e-Cidadania: Marcado automático de respuestas ciudadanas en videos de audiencias públicas | C3: 2025 | D3: Implementación de IA para identificar y marcar en los videos de eventos las respuestas dadas a preguntas ciudadanas, incluso cuando estas no fueron respondidas directamente durante las audiencias. | E3: Senado Federal de Brasil | F3: Público | G3: Governanza Colaborativa | H3: Traducción Política | I3: Plataforma | J3: Gobierno | K3: Nacional | L3: Voz a Texto, LLM, NLP | M3: gobierno nacional | N3: 2 | O3: Plataforma activa; posible nivel 3 si se verifica recurrencia (override) | P3: =";"&LOWER(SUBSTITUTE(SUBSTITUTE(SUBSTITUTE(G3,"; ",";"),", ",";"),",",";"))&";" -> ;governanza colaborativa; | Q3: =";"&LOWER(SUBSTITUTE(SUBSTITUTE(SUBSTITUTE(H3,"; ",";"),", ",";"),",",";"))&";" -> ;traducción política; | R3: =";"&LOWER(SUBSTITUTE(SUBSTITUTE(SUBSTITUTE(J3,"; ",";"),", ",";"),",",";"))&";" -> ;gobierno; | S3: =";"&LOWER(SUBSTITUTE(SUBSTITUTE(SUBSTITUTE(K3,"; ",";"),", ",";"),",",";"))&";" -> ;nacional; | T3: =";"&LOWER(SUBSTITUTE(SUBSTITUTE(SUBSTITUTE(L3,"; ",";"),", ",";"),",",";"))&";" -> ;voz a texto;llm;nlp; | U3: =";"&LOWER(SUBSTITUTE(SUBSTITUTE(SUBSTITUTE(M3,"; ",";"),", ",";"),",",";"))&";" -> ;gobierno nacional; | V3: =IF(ISNUMBER(SEARCH(";participación digital;",P3)),1,0) -> 0 | W3: =IF(OR(ISNUMBER(SEARCH(";governanza colaborativa;",P3)),ISNUMBER(SEARCH(";gobernanza colaborativa;",P3))),1,0) -> 1 | X3: =IF(ISNUMBER(SEARCH(";mini públicos;",P3)),1,0) -> 0 | Y3: =IF(ISNUMBER(SEARCH(";referendos e iniciativas populares;",P3)),1,0) -> 0 | Z3: =IF(ISNUMBER(SEARCH(";presupuestos participativos;",P3)),1,0) -> 0 | AA3: =IF(ISNUMBER(SEARCH("planif",Q3)),1,0) -> 0 | AB3: =IF(ISNUMBER(SEARCH("implement",Q3)),1,0) -> 0 | AC3: =IF(ISNUMBER(SEARCH("análisis",Q3)),1,0) -> 0 | AD3: =IF(ISNUMBER(SEARCH("traducción",Q3)),1,0) -> 1 | AE3: =IF(ISNUMBER(SEARCH("público",F3)),1,0) -> 1 | AF3: =IF(ISNUMBER(SEARCH("privado",F3)),1,0) -> 0 | AG3: =IF(ISNUMBER(SEARCH("mixto",F3)),1,0) -> 0 | AH3: =IF(ISNUMBER(SEARCH("único",I3)),1,0) -> 0 | AI3: =IF(ISNUMBER(SEARCH("plataforma",I3)),1,0) -> 1 | AJ3: =IF(ISNUMBER(SEARCH(";industria;",R3)),1,0) -> 0 | AK3: =IF(ISNUMBER(SEARCH(";academia;",R3)),1,0) -> 0 | AL3: =IF(ISNUMBER(SEARCH(";gobierno;",R3)),1,0) -> 1 | AM3: =IF(ISNUMBER(SEARCH(";sociedad civil;",R3)),1,0) -> 0 | AN3: =IF(ISNUMBER(SEARCH(";nacional;",S3)),1,0) -> 1 | AO3: =IF(ISNUMBER(SEARCH(";internacional;",S3)),1,0) -> 0 | AP3: =IF(ISNUMBER(SEARCH(";gobierno local;",U3)),1,0) -> 0 | AQ3: =IF(ISNUMBER(SEARCH(";gobierno nacional;",U3)),1,0) -> 1 | AR3: =IF(ISNUMBER(SEARCH(";otra institución pública;",U3)),1,0) -> 0 | AS3: =IF(ISNUMBER(SEARCH(";empresa;",U3)),1,0) -> 0 | AT3: =IF(ISNUMBER(SEARCH(";universidad;",U3)),1,0) -> 0 | AU3: =IF(ISNUMBER(SEARCH(";sociedad civil;",U3)),1,0) -> 0 | AV3: =IF(ISNUMBER(SEARCH(";organización internacional;",U3)),1,0) -> 0 | AW3: =IF(N3="","",IF(AND(N3=1,('3 · Cálculo 2025 · f. nueva'!$C$25-C3)>'3 · Cálculo 2025 · f. nueva'!$C$26),0,N3)) -> 2 | AX3: =IF(SUM(AP3:AV3)<2,"",IF(AP3=1,"GL+","")&IF(AQ3=1,"GN+","")&IF(AR3=1,"OIP+","")&IF(AS3=1,"EMP+","")&IF(AT3=1,"UNI+","")&IF(AU3=1,"SC+","")&IF(AV3=1,"OI+","")) | AY3: =IF(AX3="",0,IF(COUNTIFS($A$1:A2,A3,$AX$1:AX2,AX3)=0,1,0)) -> 0
A4: BR | B4: Plan Plurianual de la ciudad de Natal | C4: 2025 | D4: Recolección de información a través de tres preguntas habilitadas por WhatsApp para diseñar el Plan Plurianual de la ciudad 2026-2029 | E4: Prefeitura Municipal de Natal, a través de la Secretaría Municipal de Planeamiento (SEMPLA) | F4: Público | G4: Governanza Colaborativa | H4: Implementación, Análisis | I4: Plataforma | J4: Gobierno, Industria | K4: Nacional, Internacional | L4: LLM, NLP | M4: gobierno local | N4: 2 | P4: =";"&LOWER(SUBSTITUTE(SUBSTITUTE(SUBSTITUTE(G4,"; ",";"),", ",";"),",",";"))&";" -> ;governanza colaborativa; | Q4: =";"&LOWER(SUBSTITUTE(SUBSTITUTE(SUBSTITUTE(H4,"; ",";"),", ",";"),",",";"))&";" -> ;implementación;análisis; | R4: =";"&LOWER(SUBSTITUTE(SUBSTITUTE(SUBSTITUTE(J4,"; ",";"),", ",";"),",",";"))&";" -> ;gobierno;industria; | S4: =";"&LOWER(SUBSTITUTE(SUBSTITUTE(SUBSTITUTE(K4,"; ",";"),", ",";"),",",";"))&";" -> ;nacional;internacional; | T4: =";"&LOWER(SUBSTITUTE(SUBSTITUTE(SUBSTITUTE(L4,"; ",";"),", ",";"),",",";"))&";" -> ;llm;nlp; | U4: =";"&LOWER(SUBSTITUTE(SUBSTITUTE(SUBSTITUTE(M4,"; ",";"),", ",";"),",",";"))&";" -> ;gobierno local; | V4: =IF(ISNUMBER(SEARCH(";participación digital;",P4)),1,0) -> 0 | W4: =IF(OR(ISNUMBER(SEARCH(";governanza colaborativa;",P4)),ISNUMBER(SEARCH(";gobernanza colaborativa;",P4))),1,0) -> 1 | X4: =IF(ISNUMBER(SEARCH(";mini públicos;",P4)),1,0) -> 0 | Y4: =IF(ISNUMBER(SEARCH(";referendos e iniciativas populares;",P4)),1,0) -> 0 | Z4: =IF(ISNUMBER(SEARCH(";presupuestos participativos;",P4)),1,0) -> 0 | AA4: =IF(ISNUMBER(SEARCH("planif",Q4)),1,0) -> 0 | AB4: =IF(ISNUMBER(SEARCH("implement",Q4)),1,0) -> 1 | AC4: =IF(ISNUMBER(SEARCH("análisis",Q4)),1,0) -> 1 | AD4: =IF(ISNUMBER(SEARCH("traducción",Q4)),1,0) -> 0 | AE4: =IF(ISNUMBER(SEARCH("público",F4)),1,0) -> 1 | AF4: =IF(ISNUMBER(SEARCH("privado",F4)),1,0) -> 0 | AG4: =IF(ISNUMBER(SEARCH("mixto",F4)),1,0) -> 0 | AH4: =IF(ISNUMBER(SEARCH("único",I4)),1,0) -> 0 | AI4: =IF(ISNUMBER(SEARCH("plataforma",I4)),1,0) -> 1 | AJ4: =IF(ISNUMBER(SEARCH(";industria;",R4)),1,0) -> 1 | AK4: =IF(ISNUMBER(SEARCH(";academia;",R4)),1,0) -> 0 | AL4: =IF(ISNUMBER(SEARCH(";gobierno;",R4)),1,0) -> 1 | AM4: =IF(ISNUMBER(SEARCH(";sociedad civil;",R4)),1,0) -> 0 | AN4: =IF(ISNUMBER(SEARCH(";nacional;",S4)),1,0) -> 1 | AO4: =IF(ISNUMBER(SEARCH(";internacional;",S4)),1,0) -> 1 | AP4: =IF(ISNUMBER(SEARCH(";gobierno local;",U4)),1,0) -> 1 | AQ4: =IF(ISNUMBER(SEARCH(";gobierno nacional;",U4)),1,0) -> 0 | AR4: =IF(ISNUMBER(SEARCH(";otra institución pública;",U4)),1,0) -> 0 | AS4: =IF(ISNUMBER(SEARCH(";empresa;",U4)),1,0) -> 0 | AT4: =IF(ISNUMBER(SEARCH(";universidad;",U4)),1,0) -> 0 | AU4: =IF(ISNUMBER(SEARCH(";sociedad civil;",U4)),1,0) -> 0 | AV4: =IF(ISNUMBER(SEARCH(";organización internacional;",U4)),1,0) -> 0 | AW4: =IF(N4="","",IF(AND(N4=1,('3 · Cálculo 2025 · f. nueva'!$C$25-C4)>'3 · Cálculo 2025 · f. nueva'!$C$26),0,N4)) -> 2 | AX4: =IF(SUM(AP4:AV4)<2,"",IF(AP4=1,"GL+","")&IF(AQ4=1,"GN+","")&IF(AR4=1,"OIP+","")&IF(AS4=1,"EMP+","")&IF(AT4=1,"UNI+","")&IF(AU4=1,"SC+","")&IF(AV4=1,"OI+","")) | AY4: =IF(AX4="",0,IF(COUNTIFS($A$1:A3,A4,$AX$1:AX3,AX4)=0,1,0)) -> 0
A5: BR | B5: Colab | C5: 2013 | D5: Colab es una plataforma GovTech que permite a los ciudadanos reportar problemas urbanos, sugerir ideas, participar en encuestas y votar en decisiones municipales. Utiliza IA para optimizar la gestión pública, automatizar procesos y mejorar la eficiencia en la prestación de servicios públicos. Entre los servicios que ofrece están las consultas. | E5: Colab | F5: Privado | G5: Governanza Colaborativa | H5: Análisis | I5: Plataforma | J5: Industria | K5: Nacional | L5: ML - Inespecífico | M5: empresa | N5: 2 | O5: Plataforma desde 2013; posible nivel 3 con evidencia de recurrencia | P5: =";"&LOWER(SUBSTITUTE(SUBSTITUTE(SUBSTITUTE(G5,"; ",";"),", ",";"),",",";"))&";" -> ;governanza colaborativa; | Q5: =";"&LOWER(SUBSTITUTE(SUBSTITUTE(SUBSTITUTE(H5,"; ",";"),", ",";"),",",";"))&";" -> ;análisis; | R5: =";"&LOWER(SUBSTITUTE(SUBSTITUTE(SUBSTITUTE(J5,"; ",";"),", ",";"),",",";"))&";" -> ;industria; | S5: =";"&LOWER(SUBSTITUTE(SUBSTITUTE(SUBSTITUTE(K5,"; ",";"),", ",";"),",",";"))&";" -> ;nacional; | T5: =";"&LOWER(SUBSTITUTE(SUBSTITUTE(SUBSTITUTE(L5,"; ",";"),", ",";"),",",";"))&";" -> ;ml - inespecífico; | U5: =";"&LOWER(SUBSTITUTE(SUBSTITUTE(SUBSTITUTE(M5,"; ",";"),", ",";"),",",";"))&";" -> ;empresa; | V5: =IF(ISNUMBER(SEARCH(";participación digital;",P5)),1,0) -> 0 | W5: =IF(OR(ISNUMBER(SEARCH(";governanza colaborativa;",P5)),ISNUMBER(SEARCH(";gobernanza colaborativa;",P5))),1,0) -> 1 | X5: =IF(ISNUMBER(SEARCH(";mini públicos;",P5)),1,0) -> 0 | Y5: =IF(ISNUMBER(SEARCH(";referendos e iniciativas populares;",P5)),1,0) -> 0 | Z5: =IF(ISNUMBER(SEARCH(";presupuestos participativos;",P5)),1,0) -> 0 | AA5: =IF(ISNUMBER(SEARCH("planif",Q5)),1,0) -> 0 | AB5: =IF(ISNUMBER(SEARCH("implement",Q5)),1,0) -> 0 | AC5: =IF(ISNUMBER(SEARCH("análisis",Q5)),1,0) -> 1 | AD5: =IF(ISNUMBER(SEARCH("traducción",Q5)),1,0) -> 0 | AE5: =IF(ISNUMBER(SEARCH("público",F5)),1,0) -> 0 | AF5: =IF(ISNUMBER(SEARCH("privado",F5)),1,0) -> 1 | AG5: =IF(ISNUMBER(SEARCH("mixto",F5)),1,0) -> 0 | AH5: =IF(ISNUMBER(SEARCH("único",I5)),1,0) -> 0 | AI5: =IF(ISNUMBER(SEARCH("plataforma",I5)),1,0) -> 1 | AJ5: =IF(ISNUMBER(SEARCH(";industria;",R5)),1,0) -> 1 | AK5: =IF(ISNUMBER(SEARCH(";academia;",R5)),1,0) -> 0 | AL5: =IF(ISNUMBER(SEARCH(";gobierno;",R5)),1,0) -> 0 | AM5: =IF(ISNUMBER(SEARCH(";sociedad civil;",R5)),1,0) -> 0 | AN5: =IF(ISNUMBER(SEARCH(";nacional;",S5)),1,0) -> 1 | AO5: =IF(ISNUMBER(SEARCH(";internacional;",S5)),1,0) -> 0 | AP5: =IF(ISNUMBER(SEARCH(";gobierno local;",U5)),1,0) -> 0 | AQ5: =IF(ISNUMBER(SEARCH(";gobierno nacional;",U5)),1,0) -> 0 | AR5: =IF(ISNUMBER(SEARCH(";otra institución pública;",U5)),1,0) -> 0 | AS5: =IF(ISNUMBER(SEARCH(";empresa;",U5)),1,0) -> 1 | AT5: =IF(ISNUMBER(SEARCH(";universidad;",U5)),1,0) -> 0 | AU5: =IF(ISNUMBER(SEARCH(";sociedad civil;",U5)),1,0) -> 0 | AV5: =IF(ISNUMBER(SEARCH(";organización internacional;",U5)),1,0) -> 0 | AW5: =IF(N5="","",IF(AND(N5=1,('3 · Cálculo 2025 · f. nueva'!$C$25-C5)>'3 · Cálculo 2025 · f. nueva'!$C$26),0,N5)) -> 2 | AX5: =IF(SUM(AP5:AV5)<2,"",IF(AP5=1,"GL+","")&IF(AQ5=1,"GN+","")&IF(AR5=1,"OIP+","")&IF(AS5=1,"EMP+","")&IF(AT5=1,"UNI+","")&IF(AU5=1,"SC+","")&IF(AV5=1,"OI+","")) | AY5: =IF(AX5="",0,IF(COUNTIFS($A$1:A4,A5,$AX$1:AX4,AX5)=0,1,0)) -> 0
A6: BR | B6: ParticipACT Brasil | C6: 2018 | D6: ParticipAct es una plataforma brasileña de ciencia ciudadana de código abierto que permite a los ciudadanos reportar problemas urbanos directamente a las agencias públicas a través de una aplicación web y móvil. Utiliza inteligencia artificial para facilitar el registro de los reportes, analizar los datos y mejorar la comunicación con el público mediante chatbots, con el fin de fomentar la colaboración para resolver los problemas de la ciudad. | E6: ParticipAct | F6: Privado | G6: Governanza Colaborativa | H6: Análisis, Implementación, Traducción Política | I6: Plataforma | J6: Academia | K6: Nacional | L6: NLP, Chatbot - Inespecífico, ML - Inespecífico | M6: universidad | N6: 2 | O6: Convocante ambiguo: universidad vs sociedad civil | P6: =";"&LOWER(SUBSTITUTE(SUBSTITUTE(SUBSTITUTE(G6,"; ",";"),", ",";"),",",";"))&";" -> ;governanza colaborativa; | Q6: =";"&LOWER(SUBSTITUTE(SUBSTITUTE(SUBSTITUTE(H6,"; ",";"),", ",";"),",",";"))&";" -> ;análisis;implementación;traducción política; | R6: =";"&LOWER(SUBSTITUTE(SUBSTITUTE(SUBSTITUTE(J6,"; ",";"),", ",";"),",",";"))&";" -> ;academia; | S6: =";"&LOWER(SUBSTITUTE(SUBSTITUTE(SUBSTITUTE(K6,"; ",";"),", ",";"),",",";"))&";" -> ;nacional; | T6: =";"&LOWER(SUBSTITUTE(SUBSTITUTE(SUBSTITUTE(L6,"; ",";"),", ",";"),",",";"))&";" -> ;nlp;chatbot - inespecífico;ml - inespecífico; | U6: =";"&LOWER(SUBSTITUTE(SUBSTITUTE(SUBSTITUTE(M6,"; ",";"),", ",";"),",",";"))&";" -> ;universidad; | V6: =IF(ISNUMBER(SEARCH(";participación digital;",P6)),1,0) -> 0 | W6: =IF(OR(ISNUMBER(SEARCH(";governanza colaborativa;",P6)),ISNUMBER(SEARCH(";gobernanza colaborativa;",P6))),1,0) -> 1 | X6: =IF(ISNUMBER(SEARCH(";mini públicos;",P6)),1,0) -> 0 | Y6: =IF(ISNUMBER(SEARCH(";referendos e iniciativas populares;",P6)),1,0) -> 0 | Z6: =IF(ISNUMBER(SEARCH(";presupuestos participativos;",P6)),1,0) -> 0 | AA6: =IF(ISNUMBER(SEARCH("planif",Q6)),1,0) -> 0 | AB6: =IF(ISNUMBER(SEARCH("implement",Q6)),1,0) -> 1 | AC6: =IF(ISNUMBER(SEARCH("análisis",Q6)),1,0) -> 1 | AD6: =IF(ISNUMBER(SEARCH("traducción",Q6)),1,0) -> 1 | AE6: =IF(ISNUMBER(SEARCH("público",F6)),1,0) -> 0 | AF6: =IF(ISNUMBER(SEARCH("privado",F6)),1,0) -> 1 | AG6: =IF(ISNUMBER(SEARCH("mixto",F6)),1,0) -> 0 | AH6: =IF(ISNUMBER(SEARCH("único",I6)),1,0) -> 0 | AI6: =IF(ISNUMBER(SEARCH("plataforma",I6)),1,0) -> 1 | AJ6: =IF(ISNUMBER(SEARCH(";industria;",R6)),1,0) -> 0 | AK6: =IF(ISNUMBER(SEARCH(";academia;",R6)),1,0) -> 1 | AL6: =IF(ISNUMBER(SEARCH(";gobierno;",R6)),1,0) -> 0 | AM6: =IF(ISNUMBER(SEARCH(";sociedad civil;",R6)),1,0) -> 0 | AN6: =IF(ISNUMBER(SEARCH(";nacional;",S6)),1,0) -> 1 | AO6: =IF(ISNUMBER(SEARCH(";internacional;",S6)),1,0) -> 0 | AP6: =IF(ISNUMBER(SEARCH(";gobierno local;",U6)),1,0) -> 0 | AQ6: =IF(ISNUMBER(SEARCH(";gobierno nacional;",U6)),1,0) -> 0 | AR6: =IF(ISNUMBER(SEARCH(";otra institución pública;",U6)),1,0) -> 0 | AS6: =IF(ISNUMBER(SEARCH(";empresa;",U6)),1,0) -> 0 | AT6: =IF(ISNUMBER(SEARCH(";universidad;",U6)),1,0) -> 1 | AU6: =IF(ISNUMBER(SEARCH(";sociedad civil;",U6)),1,0) -> 0 | AV6: =IF(ISNUMBER(SEARCH(";organización internacional;",U6)),1,0) -> 0 | AW6: =IF(N6="","",IF(AND(N6=1,('3 · Cálculo 2025 · f. nueva'!$C$25-C6)>'3 · Cálculo 2025 · f. nueva'!$C$26),0,N6)) -> 2 | AX6: =IF(SUM(AP6:AV6)<2,"",IF(AP6=1,"GL+","")&IF(AQ6=1,"GN+","")&IF(AR6=1,"OIP+","")&IF(AS6=1,"EMP+","")&IF(AT6=1,"UNI+","")&IF(AU6=1,"SC+","")&IF(AV6=1,"OI+","")) | AY6: =IF(AX6="",0,IF(COUNTIFS($A$1:A5,A6,$AX$1:AX5,AX6)=0,1,0)) -> 0
A7: CL | B7: Cabildos 2016 | C7: 2016 | D7: Análisis de los cabildos del proceso constitucional en 2016 | E7: Biblioteca del Congreso Nacional | F7: Público | G7: Governanza Colaborativa | H7: Análisis | I7: Uso único | J7: Academia | K7: Nacional | L7: NLP - Tópicos | M7: otra institución pública | N7: 2 | O7: BCN: otra institución pública vs gobierno nacional | P7: =";"&LOWER(SUBSTITUTE(SUBSTITUTE(SUBSTITUTE(G7,"; ",";"),", ",";"),",",";"))&";" -> ;governanza colaborativa; | Q7: =";"&LOWER(SUBSTITUTE(SUBSTITUTE(SUBSTITUTE(H7,"; ",";"),", ",";"),",",";"))&";" -> ;análisis; | R7: =";"&LOWER(SUBSTITUTE(SUBSTITUTE(SUBSTITUTE(J7,"; ",";"),", ",";"),",",";"))&";" -> ;academia; | S7: =";"&LOWER(SUBSTITUTE(SUBSTITUTE(SUBSTITUTE(K7,"; ",";"),", ",";"),",",";"))&";" -> ;nacional; | T7: =";"&LOWER(SUBSTITUTE(SUBSTITUTE(SUBSTITUTE(L7,"; ",";"),", ",";"),",",";"))&";" -> ;nlp - tópicos; | U7: =";"&LOWER(SUBSTITUTE(SUBSTITUTE(SUBSTITUTE(M7,"; ",";"),", ",";"),",",";"))&";" -> ;otra institución pública; | V7: =IF(ISNUMBER(SEARCH(";participación digital;",P7)),1,0) -> 0 | W7: =IF(OR(ISNUMBER(SEARCH(";governanza colaborativa;",P7)),ISNUMBER(SEARCH(";gobernanza colaborativa;",P7))),1,0) -> 1 | X7: =IF(ISNUMBER(SEARCH(";mini públicos;",P7)),1,0) -> 0 | Y7: =IF(ISNUMBER(SEARCH(";referendos e iniciativas populares;",P7)),1,0) -> 0 | Z7: =IF(ISNUMBER(SEARCH(";presupuestos participativos;",P7)),1,0) -> 0 | AA7: =IF(ISNUMBER(SEARCH("planif",Q7)),1,0) -> 0 | AB7: =IF(ISNUMBER(SEARCH("implement",Q7)),1,0) -> 0 | AC7: =IF(ISNUMBER(SEARCH("análisis",Q7)),1,0) -> 1 | AD7: =IF(ISNUMBER(SEARCH("traducción",Q7)),1,0) -> 0 | AE7: =IF(ISNUMBER(SEARCH("público",F7)),1,0) -> 1 | AF7: =IF(ISNUMBER(SEARCH("privado",F7)),1,0) -> 0 | AG7: =IF(ISNUMBER(SEARCH("mixto",F7)),1,0) -> 0 | AH7: =IF(ISNUMBER(SEARCH("único",I7)),1,0) -> 1 | AI7: =IF(ISNUMBER(SEARCH("plataforma",I7)),1,0) -> 0 | AJ7: =IF(ISNUMBER(SEARCH(";industria;",R7)),1,0) -> 0 | AK7: =IF(ISNUMBER(SEARCH(";academia;",R7)),1,0) -> 1 | AL7: =IF(ISNUMBER(SEARCH(";gobierno;",R7)),1,0) -> 0 | AM7: =IF(ISNUMBER(SEARCH(";sociedad civil;",R7)),1,0) -> 0 | AN7: =IF(ISNUMBER(SEARCH(";nacional;",S7)),1,0) -> 1 | AO7: =IF(ISNUMBER(SEARCH(";internacional;",S7)),1,0) -> 0 | AP7: =IF(ISNUMBER(SEARCH(";gobierno local;",U7)),1,0) -> 0 | AQ7: =IF(ISNUMBER(SEARCH(";gobierno nacional;",U7)),1,0) -> 0 | AR7: =IF(ISNUMBER(SEARCH(";otra institución pública;",U7)),1,0) -> 1 | AS7: =IF(ISNUMBER(SEARCH(";empresa;",U7)),1,0) -> 0 | AT7: =IF(ISNUMBER(SEARCH(";universidad;",U7)),1,0) -> 0 | AU7: =IF(ISNUMBER(SEARCH(";sociedad civil;",U7)),1,0) -> 0 | AV7: =IF(ISNUMBER(SEARCH(";organización internacional;",U7)),1,0) -> 0 | AW7: =IF(N7="","",IF(AND(N7=1,('3 · Cálculo 2025 · f. nueva'!$C$25-C7)>'3 · Cálculo 2025 · f. nueva'!$C$26),0,N7)) -> 2 | AX7: =IF(SUM(AP7:AV7)<2,"",IF(AP7=1,"GL+","")&IF(AQ7=1,"GN+","")&IF(AR7=1,"OIP+","")&IF(AS7=1,"EMP+","")&IF(AT7=1,"UNI+","")&IF(AU7=1,"SC+","")&IF(AV7=1,"OI+","")) | AY7: =IF(AX7="",0,IF(COUNTIFS($A$1:A6,A7,$AX$1:AX6,AX7)=0,1,0)) -> 0
A8: CL | B8: Estudio dIAlogos - Percepciones de Futuro | C8: 2021 | D8: Estudio que utilizó distintas herramientas de IA para conocer las percepciones de futuro de la población chilena | E8: Fundación Encuentros del Futuro y Merlín Research | F8: Mixto | G8: Governanza Colaborativa | H8: Implementación, Análisis | I8: Uso único | J8: Industria | K8: Internacional | L8: NLP | M8: sociedad civil; empresa | N8: 2 | P8: =";"&LOWER(SUBSTITUTE(SUBSTITUTE(SUBSTITUTE(G8,"; ",";"),", ",";"),",",";"))&";" -> ;governanza colaborativa; | Q8: =";"&LOWER(SUBSTITUTE(SUBSTITUTE(SUBSTITUTE(H8,"; ",";"),", ",";"),",",";"))&";" -> ;implementación;análisis; | R8: =";"&LOWER(SUBSTITUTE(SUBSTITUTE(SUBSTITUTE(J8,"; ",";"),", ",";"),",",";"))&";" -> ;industria; | S8: =";"&LOWER(SUBSTITUTE(SUBSTITUTE(SUBSTITUTE(K8,"; ",";"),", ",";"),",",";"))&";" -> ;internacional; | T8: =";"&LOWER(SUBSTITUTE(SUBSTITUTE(SUBSTITUTE(L8,"; ",";"),", ",";"),",",";"))&";" -> ;nlp; | U8: =";"&LOWER(SUBSTITUTE(SUBSTITUTE(SUBSTITUTE(M8,"; ",";"),", ",";"),",",";"))&";" -> ;sociedad civil;empresa; | V8: =IF(ISNUMBER(SEARCH(";participación digital;",P8)),1,0) -> 0 | W8: =IF(OR(ISNUMBER(SEARCH(";governanza colaborativa;",P8)),ISNUMBER(SEARCH(";gobernanza colaborativa;",P8))),1,0) -> 1 | X8: =IF(ISNUMBER(SEARCH(";mini públicos;",P8)),1,0) -> 0 | Y8: =IF(ISNUMBER(SEARCH(";referendos e iniciativas populares;",P8)),1,0) -> 0 | Z8: =IF(ISNUMBER(SEARCH(";presupuestos participativos;",P8)),1,0) -> 0 | AA8: =IF(ISNUMBER(SEARCH("planif",Q8)),1,0) -> 0 | AB8: =IF(ISNUMBER(SEARCH("implement",Q8)),1,0) -> 1 | AC8: =IF(ISNUMBER(SEARCH("análisis",Q8)),1,0) -> 1 | AD8: =IF(ISNUMBER(SEARCH("traducción",Q8)),1,0) -> 0 | AE8: =IF(ISNUMBER(SEARCH("público",F8)),1,0) -> 0 | AF8: =IF(ISNUMBER(SEARCH("privado",F8)),1,0) -> 0 | AG8: =IF(ISNUMBER(SEARCH("mixto",F8)),1,0) -> 1 | AH8: =IF(ISNUMBER(SEARCH("único",I8)),1,0) -> 1 | AI8: =IF(ISNUMBER(SEARCH("plataforma",I8)),1,0) -> 0 | AJ8: =IF(ISNUMBER(SEARCH(";industria;",R8)),1,0) -> 1 | AK8: =IF(ISNUMBER(SEARCH(";academia;",R8)),1,0) -> 0 | AL8: =IF(ISNUMBER(SEARCH(";gobierno;",R8)),1,0) -> 0 | AM8: =IF(ISNUMBER(SEARCH(";sociedad civil;",R8)),1,0) -> 0 | AN8: =IF(ISNUMBER(SEARCH(";nacional;",S8)),1,0) -> 0 | AO8: =IF(ISNUMBER(SEARCH(";internacional;",S8)),1,0) -> 1 | AP8: =IF(ISNUMBER(SEARCH(";gobierno local;",U8)),1,0) -> 0 | AQ8: =IF(ISNUMBER(SEARCH(";gobierno nacional;",U8)),1,0) -> 0 | AR8: =IF(ISNUMBER(SEARCH(";otra institución pública;",U8)),1,0) -> 0 | AS8: =IF(ISNUMBER(SEARCH(";empresa;",U8)),1,0) -> 1 | AT8: =IF(ISNUMBER(SEARCH(";universidad;",U8)),1,0) -> 0 | AU8: =IF(ISNUMBER(SEARCH(";sociedad civil;",U8)),1,0) -> 1 | AV8: =IF(ISNUMBER(SEARCH(";organización internacional;",U8)),1,0) -> 0 | AW8: =IF(N8="","",IF(AND(N8=1,('3 · Cálculo 2025 · f. nueva'!$C$25-C8)>'3 · Cálculo 2025 · f. nueva'!$C$26),0,N8)) -> 2 | AX8: =IF(SUM(AP8:AV8)<2,"",IF(AP8=1,"GL+","")&IF(AQ8=1,"GN+","")&IF(AR8=1,"OIP+","")&IF(AS8=1,"EMP+","")&IF(AT8=1,"UNI+","")&IF(AU8=1,"SC+","")&IF(AV8=1,"OI+","")) -> EMP+SC+ | AY8: =IF(AX8="",0,IF(COUNTIFS($A$1:A7,A8,$AX$1:AX7,AX8)=0,1,0)) -> 1
A9: CL | B9: Tenemos que hablar de Chile | C9: 2021 | D9: Iniciativa de diálogo y participación llevada a cabo por la UCH y PUC en el contexto de manifestaciones sociales | E9: Universidad de Chile y Pontificia Universidad Católica de Chile | F9: Mixto | G9: Governanza Colaborativa | H9: Análisis | I9: Uso único | J9: Academia | K9: Nacional | L9: NLP - Tópicos | M9: universidad | N9: 2 | O9: Escenario B: caso en revisión (puede salir) | P9: =";"&LOWER(SUBSTITUTE(SUBSTITUTE(SUBSTITUTE(G9,"; ",";"),", ",";"),",",";"))&";" -> ;governanza colaborativa; | Q9: =";"&LOWER(SUBSTITUTE(SUBSTITUTE(SUBSTITUTE(H9,"; ",";"),", ",";"),",",";"))&";" -> ;análisis; | R9: =";"&LOWER(SUBSTITUTE(SUBSTITUTE(SUBSTITUTE(J9,"; ",";"),", ",";"),",",";"))&";" -> ;academia; | S9: =";"&LOWER(SUBSTITUTE(SUBSTITUTE(SUBSTITUTE(K9,"; ",";"),", ",";"),",",";"))&";" -> ;nacional; | T9: =";"&LOWER(SUBSTITUTE(SUBSTITUTE(SUBSTITUTE(L9,"; ",";"),", ",";"),",",";"))&";" -> ;nlp - tópicos; | U9: =";"&LOWER(SUBSTITUTE(SUBSTITUTE(SUBSTITUTE(M9,"; ",";"),", ",";"),",",";"))&";" -> ;universidad; | V9: =IF(ISNUMBER(SEARCH(";participación digital;",P9)),1,0) -> 0 | W9: =IF(OR(ISNUMBER(SEARCH(";governanza colaborativa;",P9)),ISNUMBER(SEARCH(";gobernanza colaborativa;",P9))),1,0) -> 1 | X9: =IF(ISNUMBER(SEARCH(";mini públicos;",P9)),1,0) -> 0 | Y9: =IF(ISNUMBER(SEARCH(";referendos e iniciativas populares;",P9)),1,0) -> 0 | Z9: =IF(ISNUMBER(SEARCH(";presupuestos participativos;",P9)),1,0) -> 0 | AA9: =IF(ISNUMBER(SEARCH("planif",Q9)),1,0) -> 0 | AB9: =IF(ISNUMBER(SEARCH("implement",Q9)),1,0) -> 0 | AC9: =IF(ISNUMBER(SEARCH("análisis",Q9)),1,0) -> 1 | AD9: =IF(ISNUMBER(SEARCH("traducción",Q9)),1,0) -> 0 | AE9: =IF(ISNUMBER(SEARCH("público",F9)),1,0) -> 0 | AF9: =IF(ISNUMBER(SEARCH("privado",F9)),1,0) -> 0 | AG9: =IF(ISNUMBER(SEARCH("mixto",F9)),1,0) -> 1 | AH9: =IF(ISNUMBER(SEARCH("único",I9)),1,0) -> 1 | AI9: =IF(ISNUMBER(SEARCH("plataforma",I9)),1,0) -> 0 | AJ9: =IF(ISNUMBER(SEARCH(";industria;",R9)),1,0) -> 0 | AK9: =IF(ISNUMBER(SEARCH(";academia;",R9)),1,0) -> 1 | AL9: =IF(ISNUMBER(SEARCH(";gobierno;",R9)),1,0) -> 0 | AM9: =IF(ISNUMBER(SEARCH(";sociedad civil;",R9)),1,0) -> 0 | AN9: =IF(ISNUMBER(SEARCH(";nacional;",S9)),1,0) -> 1 | AO9: =IF(ISNUMBER(SEARCH(";internacional;",S9)),1,0) -> 0 | AP9: =IF(ISNUMBER(SEARCH(";gobierno local;",U9)),1,0) -> 0 | AQ9: =IF(ISNUMBER(SEARCH(";gobierno nacional;",U9)),1,0) -> 0 | AR9: =IF(ISNUMBER(SEARCH(";otra institución pública;",U9)),1,0) -> 0 | AS9: =IF(ISNUMBER(SEARCH(";empresa;",U9)),1,0) -> 0 | AT9: =IF(ISNUMBER(SEARCH(";universidad;",U9)),1,0) -> 1 | AU9: =IF(ISNUMBER(SEARCH(";sociedad civil;",U9)),1,0) -> 0 | AV9: =IF(ISNUMBER(SEARCH(";organización internacional;",U9)),1,0) -> 0 | AW9: =IF(N9="","",IF(AND(N9=1,('3 · Cálculo 2025 · f. nueva'!$C$25-C9)>'3 · Cálculo 2025 · f. nueva'!$C$26),0,N9)) -> 2 | AX9: =IF(SUM(AP9:AV9)<2,"",IF(AP9=1,"GL+","")&IF(AQ9=1,"GN+","")&IF(AR9=1,"OIP+","")&IF(AS9=1,"EMP+","")&IF(AT9=1,"UNI+","")&IF(AU9=1,"SC+","")&IF(AV9=1,"OI+","")) | AY9: =IF(AX9="",0,IF(COUNTIFS($A$1:A8,A9,$AX$1:AX8,AX9)=0,1,0)) -> 0
A10: CL | B10: Jornada de Escucha Lanzamiento Instituto de Políticas Públicas UNAB | C10: 2022 | D10: Jornadas de diálogo de la comunidad académica y otos stakeholders. | E10: Universidad Andres Bello | F10: Privado | G10: Governanza Colaborativa | H10: Análisis | I10: Uso único | J10: Industria | K10: Nacional | L10: NLP - Tópicos | M10: universidad | N10: 2 | P10: =";"&LOWER(SUBSTITUTE(SUBSTITUTE(SUBSTITUTE(G10,"; ",";"),", ",";"),",",";"))&";" -> ;governanza colaborativa; | Q10: =";"&LOWER(SUBSTITUTE(SUBSTITUTE(SUBSTITUTE(H10,"; ",";"),", ",";"),",",";"))&";" -> ;análisis; | R10: =";"&LOWER(SUBSTITUTE(SUBSTITUTE(SUBSTITUTE(J10,"; ",";"),", ",";"),",",";"))&";" -> ;industria; | S10: =";"&LOWER(SUBSTITUTE(SUBSTITUTE(SUBSTITUTE(K10,"; ",";"),", ",";"),",",";"))&";" -> ;nacional; | T10: =";"&LOWER(SUBSTITUTE(SUBSTITUTE(SUBSTITUTE(L10,"; ",";"),", ",";"),",",";"))&";" -> ;nlp - tópicos; | U10: =";"&LOWER(SUBSTITUTE(SUBSTITUTE(SUBSTITUTE(M10,"; ",";"),", ",";"),",",";"))&";" -> ;universidad; | V10: =IF(ISNUMBER(SEARCH(";participación digital;",P10)),1,0) -> 0 | W10: =IF(OR(ISNUMBER(SEARCH(";governanza colaborativa;",P10)),ISNUMBER(SEARCH(";gobernanza colaborativa;",P10))),1,0) -> 1 | X10: =IF(ISNUMBER(SEARCH(";mini públicos;",P10)),1,0) -> 0 | Y10: =IF(ISNUMBER(SEARCH(";referendos e iniciativas populares;",P10)),1,0) -> 0 | Z10: =IF(ISNUMBER(SEARCH(";presupuestos participativos;",P10)),1,0) -> 0 | AA10: =IF(ISNUMBER(SEARCH("planif",Q10)),1,0) -> 0 | AB10: =IF(ISNUMBER(SEARCH("implement",Q10)),1,0) -> 0 | AC10: =IF(ISNUMBER(SEARCH("análisis",Q10)),1,0) -> 1 | AD10: =IF(ISNUMBER(SEARCH("traducción",Q10)),1,0) -> 0 | AE10: =IF(ISNUMBER(SEARCH("público",F10)),1,0) -> 0 | AF10: =IF(ISNUMBER(SEARCH("privado",F10)),1,0) -> 1 | AG10: =IF(ISNUMBER(SEARCH("mixto",F10)),1,0) -> 0 | AH10: =IF(ISNUMBER(SEARCH("único",I10)),1,0) -> 1 | AI10: =IF(ISNUMBER(SEARCH("plataforma",I10)),1,0) -> 0 | AJ10: =IF(ISNUMBER(SEARCH(";industria;",R10)),1,0) -> 1 | AK10: =IF(ISNUMBER(SEARCH(";academia;",R10)),1,0) -> 0 | AL10: =IF(ISNUMBER(SEARCH(";gobierno;",R10)),1,0) -> 0 | AM10: =IF(ISNUMBER(SEARCH(";sociedad civil;",R10)),1,0) -> 0 | AN10: =IF(ISNUMBER(SEARCH(";nacional;",S10)),1,0) -> 1 | AO10: =IF(ISNUMBER(SEARCH(";internacional;",S10)),1,0) -> 0 | AP10: =IF(ISNUMBER(SEARCH(";gobierno local;",U10)),1,0) -> 0 | AQ10: =IF(ISNUMBER(SEARCH(";gobierno nacional;",U10)),1,0) -> 0 | AR10: =IF(ISNUMBER(SEARCH(";otra institución pública;",U10)),1,0) -> 0 | AS10: =IF(ISNUMBER(SEARCH(";empresa;",U10)),1,0) -> 0 | AT10: =IF(ISNUMBER(SEARCH(";universidad;",U10)),1,0) -> 1 | AU10: =IF(ISNUMBER(SEARCH(";sociedad civil;",U10)),1,0) -> 0 | AV10: =IF(ISNUMBER(SEARCH(";organización internacional;",U10)),1,0) -> 0 | AW10: =IF(N10="","",IF(AND(N10=1,('3 · Cálculo 2025 · f. nueva'!$C$25-C10)>'3 · Cálculo 2025 · f. nueva'!$C$26),0,N10)) -> 2 | AX10: =IF(SUM(AP10:AV10)<2,"",IF(AP10=1,"GL+","")&IF(AQ10=1,"GN+","")&IF(AR10=1,"OIP+","")&IF(AS10=1,"EMP+","")&IF(AT10=1,"UNI+","")&IF(AU10=1,"SC+","")&IF(AV10=1,"OI+","")) | AY10: =IF(AX10="",0,IF(COUNTIFS($A$1:A9,A10,$AX$1:AX9,AX10)=0,1,0)) -> 0
A11: CL | B11: Participación Ciudadana Proceso Constitucional | C11: 2023 | D11: Análisis de los resultados obtenidos de los Diálogos Ciudadanos Autoconvocados dentro del proceso constitucional | E11: Secretaría de Participación Ciudadana | F11: Público | G11: Governanza Colaborativa | H11: Análisis | I11: Uso único | J11: Industria | K11: Nacional | L11: NLP - Tópicos | M11: gobierno nacional | N11: 2 | O11: Aplica a los dos casos homónimos (autoconvocados y audiencias) | P11: =";"&LOWER(SUBSTITUTE(SUBSTITUTE(SUBSTITUTE(G11,"; ",";"),", ",";"),",",";"))&";" -> ;governanza colaborativa; | Q11: =";"&LOWER(SUBSTITUTE(SUBSTITUTE(SUBSTITUTE(H11,"; ",";"),", ",";"),",",";"))&";" -> ;análisis; | R11: =";"&LOWER(SUBSTITUTE(SUBSTITUTE(SUBSTITUTE(J11,"; ",";"),", ",";"),",",";"))&";" -> ;industria; | S11: =";"&LOWER(SUBSTITUTE(SUBSTITUTE(SUBSTITUTE(K11,"; ",";"),", ",";"),",",";"))&";" -> ;nacional; | T11: =";"&LOWER(SUBSTITUTE(SUBSTITUTE(SUBSTITUTE(L11,"; ",";"),", ",";"),",",";"))&";" -> ;nlp - tópicos; | U11: =";"&LOWER(SUBSTITUTE(SUBSTITUTE(SUBSTITUTE(M11,"; ",";"),", ",";"),",",";"))&";" -> ;gobierno nacional; | V11: =IF(ISNUMBER(SEARCH(";participación digital;",P11)),1,0) -> 0 | W11: =IF(OR(ISNUMBER(SEARCH(";governanza colaborativa;",P11)),ISNUMBER(SEARCH(";gobernanza colaborativa;",P11))),1,0) -> 1 | X11: =IF(ISNUMBER(SEARCH(";mini públicos;",P11)),1,0) -> 0 | Y11: =IF(ISNUMBER(SEARCH(";referendos e iniciativas populares;",P11)),1,0) -> 0 | Z11: =IF(ISNUMBER(SEARCH(";presupuestos participativos;",P11)),1,0) -> 0 | AA11: =IF(ISNUMBER(SEARCH("planif",Q11)),1,0) -> 0 | AB11: =IF(ISNUMBER(SEARCH("implement",Q11)),1,0) -> 0 | AC11: =IF(ISNUMBER(SEARCH("análisis",Q11)),1,0) -> 1 | AD11: =IF(ISNUMBER(SEARCH("traducción",Q11)),1,0) -> 0 | AE11: =IF(ISNUMBER(SEARCH("público",F11)),1,0) -> 1 | AF11: =IF(ISNUMBER(SEARCH("privado",F11)),1,0) -> 0 | AG11: =IF(ISNUMBER(SEARCH("mixto",F11)),1,0) -> 0 | AH11: =IF(ISNUMBER(SEARCH("único",I11)),1,0) -> 1 | AI11: =IF(ISNUMBER(SEARCH("plataforma",I11)),1,0) -> 0 | AJ11: =IF(ISNUMBER(SEARCH(";industria;",R11)),1,0) -> 1 | AK11: =IF(ISNUMBER(SEARCH(";academia;",R11)),1,0) -> 0 | AL11: =IF(ISNUMBER(SEARCH(";gobierno;",R11)),1,0) -> 0 | AM11: =IF(ISNUMBER(SEARCH(";sociedad civil;",R11)),1,0) -> 0 | AN11: =IF(ISNUMBER(SEARCH(";nacional;",S11)),1,0) -> 1 | AO11: =IF(ISNUMBER(SEARCH(";internacional;",S11)),1,0) -> 0 | AP11: =IF(ISNUMBER(SEARCH(";gobierno local;",U11)),1,0) -> 0 | AQ11: =IF(ISNUMBER(SEARCH(";gobierno nacional;",U11)),1,0) -> 1 | AR11: =IF(ISNUMBER(SEARCH(";otra institución pública;",U11)),1,0) -> 0 | AS11: =IF(ISNUMBER(SEARCH(";empresa;",U11)),1,0) -> 0 | AT11: =IF(ISNUMBER(SEARCH(";universidad;",U11)),1,0) -> 0 | AU11: =IF(ISNUMBER(SEARCH(";sociedad civil;",U11)),1,0) -> 0 | AV11: =IF(ISNUMBER(SEARCH(";organización internacional;",U11)),1,0) -> 0 | AW11: =IF(N11="","",IF(AND(N11=1,('3 · Cálculo 2025 · f. nueva'!$C$25-C11)>'3 · Cálculo 2025 · f. nueva'!$C$26),0,N11)) -> 2 | AX11: =IF(SUM(AP11:AV11)<2,"",IF(AP11=1,"GL+","")&IF(AQ11=1,"GN+","")&IF(AR11=1,"OIP+","")&IF(AS11=1,"EMP+","")&IF(AT11=1,"UNI+","")&IF(AU11=1,"SC+","")&IF(AV11=1,"OI+","")) | AY11: =IF(AX11="",0,IF(COUNTIFS($A$1:A10,A11,$AX$1:AX10,AX11)=0,1,0)) -> 0
A12: CL | B12: Participación Ciudadana Proceso Constitucional | C12: 2023 | D12: Análisis de las audiencias públicas dentro de los mecanismos de participación ciudadana en el proceso constitucional | E12: Secretaría de Participación Ciudadana | F12: Público | G12: Governanza Colaborativa | H12: Análisis | I12: Uso único | J12: Industria | K12: Nacional | L12: Voz a Texto, NLP - Tópicos | M12: gobierno nacional | N12: 2 | O12: Aplica a los dos casos homónimos (autoconvocados y audiencias) | P12: =";"&LOWER(SUBSTITUTE(SUBSTITUTE(SUBSTITUTE(G12,"; ",";"),", ",";"),",",";"))&";" -> ;governanza colaborativa; | Q12: =";"&LOWER(SUBSTITUTE(SUBSTITUTE(SUBSTITUTE(H12,"; ",";"),", ",";"),",",";"))&";" -> ;análisis; | R12: =";"&LOWER(SUBSTITUTE(SUBSTITUTE(SUBSTITUTE(J12,"; ",";"),", ",";"),",",";"))&";" -> ;industria; | S12: =";"&LOWER(SUBSTITUTE(SUBSTITUTE(SUBSTITUTE(K12,"; ",";"),", ",";"),",",";"))&";" -> ;nacional; | T12: =";"&LOWER(SUBSTITUTE(SUBSTITUTE(SUBSTITUTE(L12,"; ",";"),", ",";"),",",";"))&";" -> ;voz a texto;nlp - tópicos; | U12: =";"&LOWER(SUBSTITUTE(SUBSTITUTE(SUBSTITUTE(M12,"; ",";"),", ",";"),",",";"))&";" -> ;gobierno nacional; | V12: =IF(ISNUMBER(SEARCH(";participación digital;",P12)),1,0) -> 0 | W12: =IF(OR(ISNUMBER(SEARCH(";governanza colaborativa;",P12)),ISNUMBER(SEARCH(";gobernanza colaborativa;",P12))),1,0) -> 1 | X12: =IF(ISNUMBER(SEARCH(";mini públicos;",P12)),1,0) -> 0 | Y12: =IF(ISNUMBER(SEARCH(";referendos e iniciativas populares;",P12)),1,0) -> 0 | Z12: =IF(ISNUMBER(SEARCH(";presupuestos participativos;",P12)),1,0) -> 0 | AA12: =IF(ISNUMBER(SEARCH("planif",Q12)),1,0) -> 0 | AB12: =IF(ISNUMBER(SEARCH("implement",Q12)),1,0) -> 0 | AC12: =IF(ISNUMBER(SEARCH("análisis",Q12)),1,0) -> 1 | AD12: =IF(ISNUMBER(SEARCH("traducción",Q12)),1,0) -> 0 | AE12: =IF(ISNUMBER(SEARCH("público",F12)),1,0) -> 1 | AF12: =IF(ISNUMBER(SEARCH("privado",F12)),1,0) -> 0 | AG12: =IF(ISNUMBER(SEARCH("mixto",F12)),1,0) -> 0 | AH12: =IF(ISNUMBER(SEARCH("único",I12)),1,0) -> 1 | AI12: =IF(ISNUMBER(SEARCH("plataforma",I12)),1,0) -> 0 | AJ12: =IF(ISNUMBER(SEARCH(";industria;",R12)),1,0) -> 1 | AK12: =IF(ISNUMBER(SEARCH(";academia;",R12)),1,0) -> 0 | AL12: =IF(ISNUMBER(SEARCH(";gobierno;",R12)),1,0) -> 0 | AM12: =IF(ISNUMBER(SEARCH(";sociedad civil;",R12)),1,0) -> 0 | AN12: =IF(ISNUMBER(SEARCH(";nacional;",S12)),1,0) -> 1 | AO12: =IF(ISNUMBER(SEARCH(";internacional;",S12)),1,0) -> 0 | AP12: =IF(ISNUMBER(SEARCH(";gobierno local;",U12)),1,0) -> 0 | AQ12: =IF(ISNUMBER(SEARCH(";gobierno nacional;",U12)),1,0) -> 1 | AR12: =IF(ISNUMBER(SEARCH(";otra institución pública;",U12)),1,0) -> 0 | AS12: =IF(ISNUMBER(SEARCH(";empresa;",U12)),1,0) -> 0 | AT12: =IF(ISNUMBER(SEARCH(";universidad;",U12)),1,0) -> 0 | AU12: =IF(ISNUMBER(SEARCH(";sociedad civil;",U12)),1,0) -> 0 | AV12: =IF(ISNUMBER(SEARCH(";organización internacional;",U12)),1,0) -> 0 | AW12: =IF(N12="","",IF(AND(N12=1,('3 · Cálculo 2025 · f. nueva'!$C$25-C12)>'3 · Cálculo 2025 · f. nueva'!$C$26),0,N12)) -> 2 | AX12: =IF(SUM(AP12:AV12)<2,"",IF(AP12=1,"GL+","")&IF(AQ12=1,"GN+","")&IF(AR12=1,"OIP+","")&IF(AS12=1,"EMP+","")&IF(AT12=1,"UNI+","")&IF(AU12=1,"SC+","")&IF(AV12=1,"OI+","")) | AY12: =IF(AX12="",0,IF(COUNTIFS($A$1:A11,A12,$AX$1:AX11,AX12)=0,1,0)) -> 0
A13: CL | B13: La voz de los nuevos votantes | C13: 2023 | D13: Análisis de Lenguaje Natural para los audios transcritos de encuesta realizada en persona. | E13: Universidad Andres Bello | F13: Privado | G13: Governanza Colaborativa | H13: Implementación, Análisis | I13: Uso único | J13: Industria | K13: Nacional | L13: NLP - Tópicos | M13: universidad | N13: 2 | P13: =";"&LOWER(SUBSTITUTE(SUBSTITUTE(SUBSTITUTE(G13,"; ",";"),", ",";"),",",";"))&";" -> ;governanza colaborativa; | Q13: =";"&LOWER(SUBSTITUTE(SUBSTITUTE(SUBSTITUTE(H13,"; ",";"),", ",";"),",",";"))&";" -> ;implementación;análisis; | R13: =";"&LOWER(SUBSTITUTE(SUBSTITUTE(SUBSTITUTE(J13,"; ",";"),", ",";"),",",";"))&";" -> ;industria; | S13: =";"&LOWER(SUBSTITUTE(SUBSTITUTE(SUBSTITUTE(K13,"; ",";"),", ",";"),",",";"))&";" -> ;nacional; | T13: =";"&LOWER(SUBSTITUTE(SUBSTITUTE(SUBSTITUTE(L13,"; ",";"),", ",";"),",",";"))&";" -> ;nlp - tópicos; | U13: =";"&LOWER(SUBSTITUTE(SUBSTITUTE(SUBSTITUTE(M13,"; ",";"),", ",";"),",",";"))&";" -> ;universidad; | V13: =IF(ISNUMBER(SEARCH(";participación digital;",P13)),1,0) -> 0 | W13: =IF(OR(ISNUMBER(SEARCH(";governanza colaborativa;",P13)),ISNUMBER(SEARCH(";gobernanza colaborativa;",P13))),1,0) -> 1 | X13: =IF(ISNUMBER(SEARCH(";mini públicos;",P13)),1,0) -> 0 | Y13: =IF(ISNUMBER(SEARCH(";referendos e iniciativas populares;",P13)),1,0) -> 0 | Z13: =IF(ISNUMBER(SEARCH(";presupuestos participativos;",P13)),1,0) -> 0 | AA13: =IF(ISNUMBER(SEARCH("planif",Q13)),1,0) -> 0 | AB13: =IF(ISNUMBER(SEARCH("implement",Q13)),1,0) -> 1 | AC13: =IF(ISNUMBER(SEARCH("análisis",Q13)),1,0) -> 1 | AD13: =IF(ISNUMBER(SEARCH("traducción",Q13)),1,0) -> 0 | AE13: =IF(ISNUMBER(SEARCH("público",F13)),1,0) -> 0 | AF13: =IF(ISNUMBER(SEARCH("privado",F13)),1,0) -> 1 | AG13: =IF(ISNUMBER(SEARCH("mixto",F13)),1,0) -> 0 | AH13: =IF(ISNUMBER(SEARCH("único",I13)),1,0) -> 1 | AI13: =IF(ISNUMBER(SEARCH("plataforma",I13)),1,0) -> 0 | AJ13: =IF(ISNUMBER(SEARCH(";industria;",R13)),1,0) -> 1 | AK13: =IF(ISNUMBER(SEARCH(";academia;",R13)),1,0) -> 0 | AL13: =IF(ISNUMBER(SEARCH(";gobierno;",R13)),1,0) -> 0 | AM13: =IF(ISNUMBER(SEARCH(";sociedad civil;",R13)),1,0) -> 0 | AN13: =IF(ISNUMBER(SEARCH(";nacional;",S13)),1,0) -> 1 | AO13: =IF(ISNUMBER(SEARCH(";internacional;",S13)),1,0) -> 0 | AP13: =IF(ISNUMBER(SEARCH(";gobierno local;",U13)),1,0) -> 0 | AQ13: =IF(ISNUMBER(SEARCH(";gobierno nacional;",U13)),1,0) -> 0 | AR13: =IF(ISNUMBER(SEARCH(";otra institución pública;",U13)),1,0) -> 0 | AS13: =IF(ISNUMBER(SEARCH(";empresa;",U13)),1,0) -> 0 | AT13: =IF(ISNUMBER(SEARCH(";universidad;",U13)),1,0) -> 1 | AU13: =IF(ISNUMBER(SEARCH(";sociedad civil;",U13)),1,0) -> 0 | AV13: =IF(ISNUMBER(SEARCH(";organización internacional;",U13)),1,0) -> 0 | AW13: =IF(N13="","",IF(AND(N13=1,('3 · Cálculo 2025 · f. nueva'!$C$25-C13)>'3 · Cálculo 2025 · f. nueva'!$C$26),0,N13)) -> 2 | AX13: =IF(SUM(AP13:AV13)<2,"",IF(AP13=1,"GL+","")&IF(AQ13=1,"GN+","")&IF(AR13=1,"OIP+","")&IF(AS13=1,"EMP+","")&IF(AT13=1,"UNI+","")&IF(AU13=1,"SC+","")&IF(AV13=1,"OI+","")) | AY13: =IF(AX13="",0,IF(COUNTIFS($A$1:A12,A13,$AX$1:AX12,AX13)=0,1,0)) -> 0
A14: CL | B14: Un encuentro para la equidad de género en la movilidad en Chile | C14: 2023 | D14: Espacio participativo para levantar opiniones y propuestas de autoridades, miembros de la sociedad civil y académicos sobre la movilidad con perspectiva de género en Chile. | E14: Universidad Andres Bello | F14: Privado | G14: Governanza Colaborativa | H14: Análisis | I14: Uso único | J14: Industria | K14: Nacional | L14: NLP - Tópicos | M14: universidad | N14: 2 | P14: =";"&LOWER(SUBSTITUTE(SUBSTITUTE(SUBSTITUTE(G14,"; ",";"),", ",";"),",",";"))&";" -> ;governanza colaborativa; | Q14: =";"&LOWER(SUBSTITUTE(SUBSTITUTE(SUBSTITUTE(H14,"; ",";"),", ",";"),",",";"))&";" -> ;análisis; | R14: =";"&LOWER(SUBSTITUTE(SUBSTITUTE(SUBSTITUTE(J14,"; ",";"),", ",";"),",",";"))&";" -> ;industria; | S14: =";"&LOWER(SUBSTITUTE(SUBSTITUTE(SUBSTITUTE(K14,"; ",";"),", ",";"),",",";"))&";" -> ;nacional; | T14: =";"&LOWER(SUBSTITUTE(SUBSTITUTE(SUBSTITUTE(L14,"; ",";"),", ",";"),",",";"))&";" -> ;nlp - tópicos; | U14: =";"&LOWER(SUBSTITUTE(SUBSTITUTE(SUBSTITUTE(M14,"; ",";"),", ",";"),",",";"))&";" -> ;universidad; | V14: =IF(ISNUMBER(SEARCH(";participación digital;",P14)),1,0) -> 0 | W14: =IF(OR(ISNUMBER(SEARCH(";governanza colaborativa;",P14)),ISNUMBER(SEARCH(";gobernanza colaborativa;",P14))),1,0) -> 1 | X14: =IF(ISNUMBER(SEARCH(";mini públicos;",P14)),1,0) -> 0 | Y14: =IF(ISNUMBER(SEARCH(";referendos e iniciativas populares;",P14)),1,0) -> 0 | Z14: =IF(ISNUMBER(SEARCH(";presupuestos participativos;",P14)),1,0) -> 0 | AA14: =IF(ISNUMBER(SEARCH("planif",Q14)),1,0) -> 0 | AB14: =IF(ISNUMBER(SEARCH("implement",Q14)),1,0) -> 0 | AC14: =IF(ISNUMBER(SEARCH("análisis",Q14)),1,0) -> 1 | AD14: =IF(ISNUMBER(SEARCH("traducción",Q14)),1,0) -> 0 | AE14: =IF(ISNUMBER(SEARCH("público",F14)),1,0) -> 0 | AF14: =IF(ISNUMBER(SEARCH("privado",F14)),1,0) -> 1 | AG14: =IF(ISNUMBER(SEARCH("mixto",F14)),1,0) -> 0 | AH14: =IF(ISNUMBER(SEARCH("único",I14)),1,0) -> 1 | AI14: =IF(ISNUMBER(SEARCH("plataforma",I14)),1,0) -> 0 | AJ14: =IF(ISNUMBER(SEARCH(";industria;",R14)),1,0) -> 1 | AK14: =IF(ISNUMBER(SEARCH(";academia;",R14)),1,0) -> 0 | AL14: =IF(ISNUMBER(SEARCH(";gobierno;",R14)),1,0) -> 0 | AM14: =IF(ISNUMBER(SEARCH(";sociedad civil;",R14)),1,0) -> 0 | AN14: =IF(ISNUMBER(SEARCH(";nacional;",S14)),1,0) -> 1 | AO14: =IF(ISNUMBER(SEARCH(";internacional;",S14)),1,0) -> 0 | AP14: =IF(ISNUMBER(SEARCH(";gobierno local;",U14)),1,0) -> 0 | AQ14: =IF(ISNUMBER(SEARCH(";gobierno nacional;",U14)),1,0) -> 0 | AR14: =IF(ISNUMBER(SEARCH(";otra institución pública;",U14)),1,0) -> 0 | AS14: =IF(ISNUMBER(SEARCH(";empresa;",U14)),1,0) -> 0 | AT14: =IF(ISNUMBER(SEARCH(";universidad;",U14)),1,0) -> 1 | AU14: =IF(ISNUMBER(SEARCH(";sociedad civil;",U14)),1,0) -> 0 | AV14: =IF(ISNUMBER(SEARCH(";organización internacional;",U14)),1,0) -> 0 | AW14: =IF(N14="","",IF(AND(N14=1,('3 · Cálculo 2025 · f. nueva'!$C$25-C14)>'3 · Cálculo 2025 · f. nueva'!$C$26),0,N14)) -> 2 | AX14: =IF(SUM(AP14:AV14)<2,"",IF(AP14=1,"GL+","")&IF(AQ14=1,"GN+","")&IF(AR14=1,"OIP+","")&IF(AS14=1,"EMP+","")&IF(AT14=1,"UNI+","")&IF(AU14=1,"SC+","")&IF(AV14=1,"OI+","")) | AY14: =IF(AX14="",0,IF(COUNTIFS($A$1:A13,A14,$AX$1:AX13,AX14)=0,1,0)) -> 0
A15: CL | B15: Estrategia de Gobierno Digital. Informe proceso participativo segunda consulta ciudadana | C15: 2025 | D15: Uso de IA para analizar datos cualitativos en consulta ciudadana. | E15: Secretaría de Gobierno Digital | F15: Público | G15: Governanza Colaborativa | H15: Análisis | I15: Uso único | J15: Industria | K15: Nacional | L15: NLP - Tópicos | M15: gobierno nacional | N15: 2 | P15: =";"&LOWER(SUBSTITUTE(SUBSTITUTE(SUBSTITUTE(G15,"; ",";"),", ",";"),",",";"))&";" -> ;governanza colaborativa; | Q15: =";"&LOWER(SUBSTITUTE(SUBSTITUTE(SUBSTITUTE(H15,"; ",";"),", ",";"),",",";"))&";" -> ;análisis; | R15: =";"&LOWER(SUBSTITUTE(SUBSTITUTE(SUBSTITUTE(J15,"; ",";"),", ",";"),",",";"))&";" -> ;industria; | S15: =";"&LOWER(SUBSTITUTE(SUBSTITUTE(SUBSTITUTE(K15,"; ",";"),", ",";"),",",";"))&";" -> ;nacional; | T15: =";"&LOWER(SUBSTITUTE(SUBSTITUTE(SUBSTITUTE(L15,"; ",";"),", ",";"),",",";"))&";" -> ;nlp - tópicos; | U15: =";"&LOWER(SUBSTITUTE(SUBSTITUTE(SUBSTITUTE(M15,"; ",";"),", ",";"),",",";"))&";" -> ;gobierno nacional; | V15: =IF(ISNUMBER(SEARCH(";participación digital;",P15)),1,0) -> 0 | W15: =IF(OR(ISNUMBER(SEARCH(";governanza colaborativa;",P15)),ISNUMBER(SEARCH(";gobernanza colaborativa;",P15))),1,0) -> 1 | X15: =IF(ISNUMBER(SEARCH(";mini públicos;",P15)),1,0) -> 0 | Y15: =IF(ISNUMBER(SEARCH(";referendos e iniciativas populares;",P15)),1,0) -> 0 | Z15: =IF(ISNUMBER(SEARCH(";presupuestos participativos;",P15)),1,0) -> 0 | AA15: =IF(ISNUMBER(SEARCH("planif",Q15)),1,0) -> 0 | AB15: =IF(ISNUMBER(SEARCH("implement",Q15)),1,0) -> 0 | AC15: =IF(ISNUMBER(SEARCH("análisis",Q15)),1,0) -> 1 | AD15: =IF(ISNUMBER(SEARCH("traducción",Q15)),1,0) -> 0 | AE15: =IF(ISNUMBER(SEARCH("público",F15)),1,0) -> 1 | AF15: =IF(ISNUMBER(SEARCH("privado",F15)),1,0) -> 0 | AG15: =IF(ISNUMBER(SEARCH("mixto",F15)),1,0) -> 0 | AH15: =IF(ISNUMBER(SEARCH("único",I15)),1,0) -> 1 | AI15: =IF(ISNUMBER(SEARCH("plataforma",I15)),1,0) -> 0 | AJ15: =IF(ISNUMBER(SEARCH(";industria;",R15)),1,0) -> 1 | AK15: =IF(ISNUMBER(SEARCH(";academia;",R15)),1,0) -> 0 | AL15: =IF(ISNUMBER(SEARCH(";gobierno;",R15)),1,0) -> 0 | AM15: =IF(ISNUMBER(SEARCH(";sociedad civil;",R15)),1,0) -> 0 | AN15: =IF(ISNUMBER(SEARCH(";nacional;",S15)),1,0) -> 1 | AO15: =IF(ISNUMBER(SEARCH(";internacional;",S15)),1,0) -> 0 | AP15: =IF(ISNUMBER(SEARCH(";gobierno local;",U15)),1,0) -> 0 | AQ15: =IF(ISNUMBER(SEARCH(";gobierno nacional;",U15)),1,0) -> 1 | AR15: =IF(ISNUMBER(SEARCH(";otra institución pública;",U15)),1,0) -> 0 | AS15: =IF(ISNUMBER(SEARCH(";empresa;",U15)),1,0) -> 0 | AT15: =IF(ISNUMBER(SEARCH(";universidad;",U15)),1,0) -> 0 | AU15: =IF(ISNUMBER(SEARCH(";sociedad civil;",U15)),1,0) -> 0 | AV15: =IF(ISNUMBER(SEARCH(";organización internacional;",U15)),1,0) -> 0 | AW15: =IF(N15="","",IF(AND(N15=1,('3 · Cálculo 2025 · f. nueva'!$C$25-C15)>'3 · Cálculo 2025 · f. nueva'!$C$26),0,N15)) -> 2 | AX15: =IF(SUM(AP15:AV15)<2,"",IF(AP15=1,"GL+","")&IF(AQ15=1,"GN+","")&IF(AR15=1,"OIP+","")&IF(AS15=1,"EMP+","")&IF(AT15=1,"UNI+","")&IF(AU15=1,"SC+","")&IF(AV15=1,"OI+","")) | AY15: =IF(AX15="",0,IF(COUNTIFS($A$1:A14,A15,$AX$1:AX14,AX15)=0,1,0)) -> 0
A16: CO | B16: ECHO – HáblameD Medellín | C16: 2019 | D16: IA que capta voz ciudadana en debates guiados y clasifica cada enunciado en metas ODS, generando visualizaciones para la planificación territorial | E16: UNFPA Colombia (Laboratorio de Innovación) y Personería de Medellín | F16: Mixto | G16: Governanza Colaborativa | H16: Implementación, Análisis | I16: Uso único | J16: Gobierno | K16: Internacional | L16: Voz a Texto, NLP, LLM | M16: organización internacional; gobierno local | N16: 2 | P16: =";"&LOWER(SUBSTITUTE(SUBSTITUTE(SUBSTITUTE(G16,"; ",";"),", ",";"),",",";"))&";" -> ;governanza colaborativa; | Q16: =";"&LOWER(SUBSTITUTE(SUBSTITUTE(SUBSTITUTE(H16,"; ",";"),", ",";"),",",";"))&";" -> ;implementación;análisis; | R16: =";"&LOWER(SUBSTITUTE(SUBSTITUTE(SUBSTITUTE(J16,"; ",";"),", ",";"),",",";"))&";" -> ;gobierno; | S16: =";"&LOWER(SUBSTITUTE(SUBSTITUTE(SUBSTITUTE(K16,"; ",";"),", ",";"),",",";"))&";" -> ;internacional; | T16: =";"&LOWER(SUBSTITUTE(SUBSTITUTE(SUBSTITUTE(L16,"; ",";"),", ",";"),",",";"))&";" -> ;voz a texto;nlp;llm; | U16: =";"&LOWER(SUBSTITUTE(SUBSTITUTE(SUBSTITUTE(M16,"; ",";"),", ",";"),",",";"))&";" -> ;organización internacional;gobierno local; | V16: =IF(ISNUMBER(SEARCH(";participación digital;",P16)),1,0) -> 0 | W16: =IF(OR(ISNUMBER(SEARCH(";governanza colaborativa;",P16)),ISNUMBER(SEARCH(";gobernanza colaborativa;",P16))),1,0) -> 1 | X16: =IF(ISNUMBER(SEARCH(";mini públicos;",P16)),1,0) -> 0 | Y16: =IF(ISNUMBER(SEARCH(";referendos e iniciativas populares;",P16)),1,0) -> 0 | Z16: =IF(ISNUMBER(SEARCH(";presupuestos participativos;",P16)),1,0) -> 0 | AA16: =IF(ISNUMBER(SEARCH("planif",Q16)),1,0) -> 0 | AB16: =IF(ISNUMBER(SEARCH("implement",Q16)),1,0) -> 1 | AC16: =IF(ISNUMBER(SEARCH("análisis",Q16)),1,0) -> 1 | AD16: =IF(ISNUMBER(SEARCH("traducción",Q16)),1,0) -> 0 | AE16: =IF(ISNUMBER(SEARCH("público",F16)),1,0) -> 0 | AF16: =IF(ISNUMBER(SEARCH("privado",F16)),1,0) -> 0 | AG16: =IF(ISNUMBER(SEARCH("mixto",F16)),1,0) -> 1 | AH16: =IF(ISNUMBER(SEARCH("único",I16)),1,0) -> 1 | AI16: =IF(ISNUMBER(SEARCH("plataforma",I16)),1,0) -> 0 | AJ16: =IF(ISNUMBER(SEARCH(";industria;",R16)),1,0) -> 0 | AK16: =IF(ISNUMBER(SEARCH(";academia;",R16)),1,0) -> 0 | AL16: =IF(ISNUMBER(SEARCH(";gobierno;",R16)),1,0) -> 1 | AM16: =IF(ISNUMBER(SEARCH(";sociedad civil;",R16)),1,0) -> 0 | AN16: =IF(ISNUMBER(SEARCH(";nacional;",S16)),1,0) -> 0 | AO16: =IF(ISNUMBER(SEARCH(";internacional;",S16)),1,0) -> 1 | AP16: =IF(ISNUMBER(SEARCH(";gobierno local;",U16)),1,0) -> 1 | AQ16: =IF(ISNUMBER(SEARCH(";gobierno nacional;",U16)),1,0) -> 0 | AR16: =IF(ISNUMBER(SEARCH(";otra institución pública;",U16)),1,0) -> 0 | AS16: =IF(ISNUMBER(SEARCH(";empresa;",U16)),1,0) -> 0 | AT16: =IF(ISNUMBER(SEARCH(";universidad;",U16)),1,0) -> 0 | AU16: =IF(ISNUMBER(SEARCH(";sociedad civil;",U16)),1,0) -> 0 | AV16: =IF(ISNUMBER(SEARCH(";organización internacional;",U16)),1,0) -> 1 | AW16: =IF(N16="","",IF(AND(N16=1,('3 · Cálculo 2025 · f. nueva'!$C$25-C16)>'3 · Cálculo 2025 · f. nueva'!$C$26),0,N16)) -> 2 | AX16: =IF(SUM(AP16:AV16)<2,"",IF(AP16=1,"GL+","")&IF(AQ16=1,"GN+","")&IF(AR16=1,"OIP+","")&IF(AS16=1,"EMP+","")&IF(AT16=1,"UNI+","")&IF(AU16=1,"SC+","")&IF(AV16=1,"OI+","")) -> GL+OI+ | AY16: =IF(AX16="",0,IF(COUNTIFS($A$1:A15,A16,$AX$1:AX15,AX16)=0,1,0)) -> 1
A17: CO | B17: Tenemos que hablar de Colombia | C17: 2022 | D17: Plataforma colaborativa de diálogo e incidencia ciudadana para la conversación entre diversos actores de la sociedad colombiana, surgido a partir de eventos de manifestaciones sociales. | E17: Alianza entre seis universidades colombianas (EAFIT, Universidad Nacional de Colombia, Universidad de los Andes, Universidad del Valle, Universidad del Norte y Universidad Industrial de Santander), con el apoyo del Grupo SURA y la Fundación Ideas para la Paz. | F17: Mixto | G17: Governanza Colaborativa | H17: Análisis | I17: Uso único | J17: Sociedad Civil | K17: Nacional | L17: NLP - Tópicos, NLP - Sentiment | M17: universidad; empresa; sociedad civil | N17: 2 | P17: =";"&LOWER(SUBSTITUTE(SUBSTITUTE(SUBSTITUTE(G17,"; ",";"),", ",";"),",",";"))&";" -> ;governanza colaborativa; | Q17: =";"&LOWER(SUBSTITUTE(SUBSTITUTE(SUBSTITUTE(H17,"; ",";"),", ",";"),",",";"))&";" -> ;análisis; | R17: =";"&LOWER(SUBSTITUTE(SUBSTITUTE(SUBSTITUTE(J17,"; ",";"),", ",";"),",",";"))&";" -> ;sociedad civil; | S17: =";"&LOWER(SUBSTITUTE(SUBSTITUTE(SUBSTITUTE(K17,"; ",";"),", ",";"),",",";"))&";" -> ;nacional; | T17: =";"&LOWER(SUBSTITUTE(SUBSTITUTE(SUBSTITUTE(L17,"; ",";"),", ",";"),",",";"))&";" -> ;nlp - tópicos;nlp - sentiment; | U17: =";"&LOWER(SUBSTITUTE(SUBSTITUTE(SUBSTITUTE(M17,"; ",";"),", ",";"),",",";"))&";" -> ;universidad;empresa;sociedad civil; | V17: =IF(ISNUMBER(SEARCH(";participación digital;",P17)),1,0) -> 0 | W17: =IF(OR(ISNUMBER(SEARCH(";governanza colaborativa;",P17)),ISNUMBER(SEARCH(";gobernanza colaborativa;",P17))),1,0) -> 1 | X17: =IF(ISNUMBER(SEARCH(";mini públicos;",P17)),1,0) -> 0 | Y17: =IF(ISNUMBER(SEARCH(";referendos e iniciativas populares;",P17)),1,0) -> 0 | Z17: =IF(ISNUMBER(SEARCH(";presupuestos participativos;",P17)),1,0) -> 0 | AA17: =IF(ISNUMBER(SEARCH("planif",Q17)),1,0) -> 0 | AB17: =IF(ISNUMBER(SEARCH("implement",Q17)),1,0) -> 0 | AC17: =IF(ISNUMBER(SEARCH("análisis",Q17)),1,0) -> 1 | AD17: =IF(ISNUMBER(SEARCH("traducción",Q17)),1,0) -> 0 | AE17: =IF(ISNUMBER(SEARCH("público",F17)),1,0) -> 0 | AF17: =IF(ISNUMBER(SEARCH("privado",F17)),1,0) -> 0 | AG17: =IF(ISNUMBER(SEARCH("mixto",F17)),1,0) -> 1 | AH17: =IF(ISNUMBER(SEARCH("único",I17)),1,0) -> 1 | AI17: =IF(ISNUMBER(SEARCH("plataforma",I17)),1,0) -> 0 | AJ17: =IF(ISNUMBER(SEARCH(";industria;",R17)),1,0) -> 0 | AK17: =IF(ISNUMBER(SEARCH(";academia;",R17)),1,0) -> 0 | AL17: =IF(ISNUMBER(SEARCH(";gobierno;",R17)),1,0) -> 0 | AM17: =IF(ISNUMBER(SEARCH(";sociedad civil;",R17)),1,0) -> 1 | AN17: =IF(ISNUMBER(SEARCH(";nacional;",S17)),1,0) -> 1 | AO17: =IF(ISNUMBER(SEARCH(";internacional;",S17)),1,0) -> 0 | AP17: =IF(ISNUMBER(SEARCH(";gobierno local;",U17)),1,0) -> 0 | AQ17: =IF(ISNUMBER(SEARCH(";gobierno nacional;",U17)),1,0) -> 0 | AR17: =IF(ISNUMBER(SEARCH(";otra institución pública;",U17)),1,0) -> 0 | AS17: =IF(ISNUMBER(SEARCH(";empresa;",U17)),1,0) -> 1 | AT17: =IF(ISNUMBER(SEARCH(";universidad;",U17)),1,0) -> 1 | AU17: =IF(ISNUMBER(SEARCH(";sociedad civil;",U17)),1,0) -> 1 | AV17: =IF(ISNUMBER(SEARCH(";organización internacional;",U17)),1,0) -> 0 | AW17: =IF(N17="","",IF(AND(N17=1,('3 · Cálculo 2025 · f. nueva'!$C$25-C17)>'3 · Cálculo 2025 · f. nueva'!$C$26),0,N17)) -> 2 | AX17: =IF(SUM(AP17:AV17)<2,"",IF(AP17=1,"GL+","")&IF(AQ17=1,"GN+","")&IF(AR17=1,"OIP+","")&IF(AS17=1,"EMP+","")&IF(AT17=1,"UNI+","")&IF(AU17=1,"SC+","")&IF(AV17=1,"OI+","")) -> EMP+UNI+SC+ | AY17: =IF(AX17="",0,IF(COUNTIFS($A$1:A16,A17,$AX$1:AX16,AX17)=0,1,0)) -> 1
A18: CO | B18: Chatico | C18: 2024 | D18: Atención automatizada mediante procesamiento de lenguaje natural, análisis de datos y algoritmos de inteligencia artificial para responder consultas ciudadanas sobre más de 400 temas de interés. | E18: Secretaría General de la Alcaldía Mayor de Bogotá | F18: Público | G18: Referendos e Iniciativas Populares, Presupuestos Participativos | H18: Implementación | I18: Plataforma | J18: Industria, Gobierno | K18: Nacional | L18: NLP, LLM | M18: gobierno local | N18: 2 | P18: =";"&LOWER(SUBSTITUTE(SUBSTITUTE(SUBSTITUTE(G18,"; ",";"),", ",";"),",",";"))&";" -> ;referendos e iniciativas populares;presupuestos participativos; | Q18: =";"&LOWER(SUBSTITUTE(SUBSTITUTE(SUBSTITUTE(H18,"; ",";"),", ",";"),",",";"))&";" -> ;implementación; | R18: =";"&LOWER(SUBSTITUTE(SUBSTITUTE(SUBSTITUTE(J18,"; ",";"),", ",";"),",",";"))&";" -> ;industria;gobierno; | S18: =";"&LOWER(SUBSTITUTE(SUBSTITUTE(SUBSTITUTE(K18,"; ",";"),", ",";"),",",";"))&";" -> ;nacional; | T18: =";"&LOWER(SUBSTITUTE(SUBSTITUTE(SUBSTITUTE(L18,"; ",";"),", ",";"),",",";"))&";" -> ;nlp;llm; | U18: =";"&LOWER(SUBSTITUTE(SUBSTITUTE(SUBSTITUTE(M18,"; ",";"),", ",";"),",",";"))&";" -> ;gobierno local; | V18: =IF(ISNUMBER(SEARCH(";participación digital;",P18)),1,0) -> 0 | W18: =IF(OR(ISNUMBER(SEARCH(";governanza colaborativa;",P18)),ISNUMBER(SEARCH(";gobernanza colaborativa;",P18))),1,0) -> 0 | X18: =IF(ISNUMBER(SEARCH(";mini públicos;",P18)),1,0) -> 0 | Y18: =IF(ISNUMBER(SEARCH(";referendos e iniciativas populares;",P18)),1,0) -> 1 | Z18: =IF(ISNUMBER(SEARCH(";presupuestos participativos;",P18)),1,0) -> 1 | AA18: =IF(ISNUMBER(SEARCH("planif",Q18)),1,0) -> 0 | AB18: =IF(ISNUMBER(SEARCH("implement",Q18)),1,0) -> 1 | AC18: =IF(ISNUMBER(SEARCH("análisis",Q18)),1,0) -> 0 | AD18: =IF(ISNUMBER(SEARCH("traducción",Q18)),1,0) -> 0 | AE18: =IF(ISNUMBER(SEARCH("público",F18)),1,0) -> 1 | AF18: =IF(ISNUMBER(SEARCH("privado",F18)),1,0) -> 0 | AG18: =IF(ISNUMBER(SEARCH("mixto",F18)),1,0) -> 0 | AH18: =IF(ISNUMBER(SEARCH("único",I18)),1,0) -> 0 | AI18: =IF(ISNUMBER(SEARCH("plataforma",I18)),1,0) -> 1 | AJ18: =IF(ISNUMBER(SEARCH(";industria;",R18)),1,0) -> 1 | AK18: =IF(ISNUMBER(SEARCH(";academia;",R18)),1,0) -> 0 | AL18: =IF(ISNUMBER(SEARCH(";gobierno;",R18)),1,0) -> 1 | AM18: =IF(ISNUMBER(SEARCH(";sociedad civil;",R18)),1,0) -> 0 | AN18: =IF(ISNUMBER(SEARCH(";nacional;",S18)),1,0) -> 1 | AO18: =IF(ISNUMBER(SEARCH(";internacional;",S18)),1,0) -> 0 | AP18: =IF(ISNUMBER(SEARCH(";gobierno local;",U18)),1,0) -> 1 | AQ18: =IF(ISNUMBER(SEARCH(";gobierno nacional;",U18)),1,0) -> 0 | AR18: =IF(ISNUMBER(SEARCH(";otra institución pública;",U18)),1,0) -> 0 | AS18: =IF(ISNUMBER(SEARCH(";empresa;",U18)),1,0) -> 0 | AT18: =IF(ISNUMBER(SEARCH(";universidad;",U18)),1,0) -> 0 | AU18: =IF(ISNUMBER(SEARCH(";sociedad civil;",U18)),1,0) -> 0 | AV18: =IF(ISNUMBER(SEARCH(";organización internacional;",U18)),1,0) -> 0 | AW18: =IF(N18="","",IF(AND(N18=1,('3 · Cálculo 2025 · f. nueva'!$C$25-C18)>'3 · Cálculo 2025 · f. nueva'!$C$26),0,N18)) -> 2 | AX18: =IF(SUM(AP18:AV18)<2,"",IF(AP18=1,"GL+","")&IF(AQ18=1,"GN+","")&IF(AR18=1,"OIP+","")&IF(AS18=1,"EMP+","")&IF(AT18=1,"UNI+","")&IF(AU18=1,"SC+","")&IF(AV18=1,"OI+","")) | AY18: =IF(AX18="",0,IF(COUNTIFS($A$1:A17,A18,$AX$1:AX17,AX18)=0,1,0)) -> 0
